Workbook

Sheet DATABASE
A1: DATABASE POSYANDU
B2: DESA | C2: : TEGAL YOSO
A4: NO | B4: NAMA POSYANDU | C4: HARI BUKA | D4: JUMLAH RUMAH | E4: JUMLAH KK | F4: JUMLAH PENDUDUK | G4: JUMLAH ANAK USIA 3-6 THN | H4: JUMLAH ANAK USIA SD | I4: JUMLAH USIA PRODUKTIF | J4: JUMLAH LANSIA | K4: JUMLAH DISABILITAS | L4: STATUS BANGUNAN POSYANDU | N4: DANA SEHAT | P4: JUMLAH KADER | Q4: STRATA POSYANDU | R4: KEGIATAN INTEGRASI
L5: MILIK SENDIRI | M5: MENUMPANG | N5: ADA | O5: TIDAK ADA
A6: 1 | B6: Dahlia | C6: Selasa ke-1 | D6: 147 | E6: 154 | F6: 511 | H6: 33 | I6: 264 | J6: 59 | K6: 13 | M6: 1 | P6: 7 | Q6: Mandiri | R6: Posyandu ILP
A7: 2 | B7: Kenanga | C7: Senin ke-1 | D7: 97 | E7: 104 | F7: 319 | H7: 18 | I7: 191 | J7: 51 | K7: 2 | M7: 1 | P7: 7 | Q7: Mandiri | R7: Posyandu ILP
A8: 3 | B8: Mawar | C8: Rabu ke-1 | D8: 170 | E8: 196 | F8: 625 | H8: 115 | J8: 69 | K8: 3 | M8: 1 | P8: 7 | Q8: Mandiri | R8: Posyandu ILP
A9: 4 | B9: Melati | C9: Senin ke-2 | E9: 150 | F9: 490 | H9: 211 | J9: 75 | K9: 1 | M9: 1 | P9: 7 | Q9: Mandiri | R9: Posyandu ILP
A10: 5 | B10: Anggrek | C10: Selasa ke-2 | D10: 220 | E10: 264 | F10: 821 | H10: 58 | I10: 370 | J10: 138 | K10: 5 | M10: 1 | P10: 7 | Q10: Mandiri | R10: Posyandu ILP
A11: 6 | B11: Cempaka | C11: Rabu ke-2 | D11: 186 | E11: 210 | F11: 695 | I11: 541 | J11: 95 | K11: 0 | M11: 1 | P11: 7 | Q11: Mandiri | R11: Posyandu ILP
Q12: Mandiri | R12: Posyandu ILP
A13: JUMLAH | D13: =SUM(D6:D12) -> 820 | E13: =SUM(E6:E12) -> 1078 | F13: =SUM(F6:F12) -> 3461 | G13: =SUM(G6:G12) -> 0 | H13: =SUM(H6:H12) -> 435 | I13: =SUM(I6:I12) -> 1366 | J13: =SUM(J6:J12) -> 487 | K13: =SUM(K6:K12) -> 24 | ... P13: =SUM(P6:P12) -> 42 | Q13: 6 | R13: =SUM(R6:R12) -> 0

Sheet PENDIDIKAN
A1: LAPORAN POSYANDU
A2: BIDANG PENDIDIKAN
B3: DESA | C3: : TEGAL YOSO
A5: No | B5: tanggal | C5: Posyandu | D5: NIK | E5: Nama | F5: Alamat | G5: Hal pengaduan | H5: Keterangan
H6: TL | I6: BTL
A7: 1 | B7: 2 | C7: 3 | D7: 4 | E7: 5 | F7: 6 | G7: 7 | H7: 8 | I7: 9
A8: 1 | B8: 16-06-2025 | C8: =DATABASE!B6 -> Dahlia | D8: 1807231503090001 | E8: YANTI NURHAYATI | F8: RT 10/25 | G8: Tidak ada biaya untuk Kuliah jadi mengajukan pembuatan KIP (contoh) | H8: Sudah diproses | I8: -
A9: 2 | C9: =DATABASE!B7 -> Kenanga | D9: 1807157110110001 | E9: ALFA SA'ADAH | F9: RT 006/002 | G9: Keterbelakangan Mental
A10: 3 | C10: =DATABASE!B8 -> Mawar
A11: 4 | C11: =DATABASE!B9 -> Melati
A12: 5 | C12: =DATABASE!B10 -> Anggrek
A13: 6 | C13: =DATABASE!B11 -> Cempaka

Sheet KESEHATAN SIP 6
A1: DATA PENGUNJUNG
B3: DESA | C3: =DATABASE!C2 -> : TEGAL YOSO
A4: NO | B4: BULAN | C4: JUMLAH PENGUNJUNG | AA4: JUMLAH PETUGAS YG HADIR | AG4: JUMLAH BAYI | AK4: KET
C5: B A L I T A | K5: ANAK USIA 6-15 TAHUN | O5: USIA PRODUKTIF | S5: LANSIA | W5: WUS | X5: IBU | AA5: KADER | AC5: PLKB | AE5: MEDIS DAN PARA MEDIS | AG5: YANG LAHIR | AI5: MENINGGAL
C6: BAYI 0 - 12 BULAN | G6: BALITA 1-5 TAHUN | X6: PUS | Y6: HAMIL | Z6: MENYUSUI
C7: BARU | E7: LAMA | G7: BARU | I7: LAMA | K7: BARU | M7: LAMA | O7: BARU | Q7: LAMA | S7: BARU | U7: LAMA
C8: L | D8: P | E8: L | F8: P | G8: L | H8: P | I8: L | J8: P | K8: L | L8: P | M8: L | N8: P | O8: L | P8: P | Q8: L | R8: P | S8: L | T8: P | U8: L | V8: P | AA8: L | AB8: P | AC8: L | AD8: P | AE8: L | AF8: P | AG8: L | AH8: P | AI8: L | AJ8: P
A9: 1 | B9: 2 | C9: 3 | D9: 4 | E9: 5 | F9: 6 | G9: 7 | H9: 8 | I9: 9 | J9: 10 | K9: 11 | L9: 12 | M9: 13 | N9: 14 | O9: 15 | P9: 16 | Q9: 17 | R9: 18 | S9: 19 | T9: 20 | U9: 21 | V9: 22 | W9: 23 | X9: 24 | Y9: 25 | Z9: 26 | AA9: 27 | AB9: 28 | AC9: 29 | AD9: 30 | AE9: 31 | AF9: 32 | AG9: 33 | AH9: 34 | AI9: 35 | AJ9: 36 | AK9: 37
A10: 1 | B10: JANUARI | C10: 1 | D10: 1 | E10: 2 | F10: 3 | G10: 0 | H10: 0 | I10: 4 | J10: 7 | K10: 0 | L10: 0 | M10: 0 | N10: 0 | O10: 0 | P10: 0 | Q10: 0 | R10: 15 | S10: 0 | T10: 0 | U10: 0 | V10: 5 | AA10: 0 | AB10: 30 | AE10: 0 | AF10: 1 | AI10: 0 | AJ10: 0
A11: 2 | B11: FEBRUARI | C11: 2 | D11: 2 | E11: 1 | F11: 2 | G11: 1 | H11: 1 | I11: 4 | J11: 7 | K11: 0 | L11: 0 | M11: 0 | N11: 0 | O11: 0 | P11: 0 | Q11: 0 | R11: 12 | S11: 0 | T11: 0 | U11: 0 | V11: 8 | AA11: 0 | AB11: 30 | AE11: 0 | AF11: 1 | AI11: 0 | AJ11: 0
A12: 3 | B12: MARET | C12: 1 | D12: 0 | E12: 0 | F12: 2 | G12: 0 | H12: 0 | I12: 6 | J12: 8 | K12: 0 | L12: 0 | M12: 0 | N12: 0 | O12: 0 | P12: 0 | Q12: 0 | R12: 13 | S12: 0 | T12: 0 | U12: 1 | V12: 4 | AA12: 0 | AB12: 30 | AE12: 0 | AF12: 1 | AI12: 0 | AJ12: 0
A13: 4 | B13: APRIL | C13: 0 | D13: 0 | E13: 1 | F13: 2 | G13: 0 | H13: 0 | I13: 6 | J13: 7 | K13: 0 | L13: 0 | M13: 0 | N13: 0 | O13: 0 | P13: 0 | Q13: 0 | R13: 12 | S13: 0 | T13: 0 | U13: 0 | V13: 4 | AA13: 0 | AB13: 42 | AE13: 0 | AF13: 1 | AI13: 0 | AJ13: 0
A14: 5 | B14: MEI | C14: 1 | D14: 0 | E14: 1 | F14: 0 | G14: 1 | H14: 0 | I14: 5 | J14: 8 | K14: 0 | L14: 0 | M14: 0 | N14: 0 | O14: 0 | P14: 0 | Q14: 0 | R14: 25 | S14: 0 | T14: 0 | U14: 0 | V14: 4 | AA14: 0 | AB14: 42 | AE14: 0 | AF14: 1 | AI14: 0 | AJ14: 0
A15: 6 | B15: JUNI | C15: 1 | D15: 0 | E15: 1 | F15: 2 | G15: 0 | H15: 0 | I15: 6 | J15: 8 | K15: 0 | L15: 0 | M15: 0 | N15: 0 | O15: 0 | P15: 0 | Q15: 1 | R15: 23 | S15: 0 | T15: 0 | U15: 0 | V15: 1 | AA15: 0 | AB15: 42 | AE15: 0 | AF15: 1 | AI15: 0 | AJ15: 0
A16: 7 | B16: JULI | C16: 4 | D16: 3 | E16: 1 | F16: 2 | G16: 0 | H16: 0 | I16: 6 | J16: 8 | K16: 0 | L16: 0 | M16: 0 | N16: 0 | O16: 0 | P16: 0 | Q16: 0 | R16: 27 | S16: 0 | T16: 0 | U16: 0 | V16: 2 | AA16: 0 | AB16: 42 | AE16: 0 | AF16: 1 | AI16: 0 | AJ16: 0
A17: 8 | B17: AGUSTUS | C17: 0 | D17: 1 | E17: 1 | F17: 2 | G17: 0 | H17: 0 | I17: 5 | J17: 8 | K17: 0 | L17: 0 | M17: 0 | N17: 0 | O17: 0 | P17: 0 | Q17: 1 | R17: 31 | S17: 0 | T17: 0 | U17: 1 | V17: 4 | AA17: 0 | AB17: 42 | AE17: 0 | AF17: 1 | AI17: 0 | AJ17: 0
A18: 9 | B18: SEPTEMBER | C18: 1 | D18: 1 | E18: 2 | F18: 2 | G18: 0 | H18: 0 | I18: 6 | J18: 9 | K18: 0 | L18: 0 | M18: 0 | N18: 0 | O18: 0 | P18: 0 | Q18: 2 | R18: 24 | S18: 0 | T18: 0 | U18: 1 | V18: 4 | AA18: 0 | AB18: 42 | AE18: 0 | AF18: 1 | AI18: 0 | AJ18: 0
A19: 10 | B19: OKTOBER | C19: 0 | D19: 1 | E19: 2 | F19: 2 | G19: 0 | H19: 0 | I19: 6 | J19: 6 | K19: 0 | L19: 0 | M19: 0 | N19: 0 | O19: 0 | P19: 0 | Q19: 0 | R19: 24 | S19: 0 | T19: 0 | U19: 0 | V19: 2 | AA19: 0 | AB19: 42 | AE19: 0 | AF19: 1 | AI19: 0 | AJ19: 0
A20: 11 | B20: NOVEMBER | C20: 0 | D20: 0 | E20: 3 | F20: 1 | G20: 0 | H20: 1 | I20: 5 | J20: 9 | K20: 0 | L20: 0 | M20: 0 | N20: 0 | O20: 0 | P20: 0 | Q20: 1 | R20: 25 | S20: 0 | T20: 0 | U20: 0 | V20: 4 | AA20: 0 | AB20: 42 | AE20: 0 | AF20: 1 | AI20: 0 | AJ20: 0
A21: 12 | B21: DESEMBER | C21: 1 | D21: 0 | K21: 0 | L21: 0 | M21: 0 | N21: 0 | O21: 0 | P21: 0 | Q21: 0 | R21: 24 | S21: 0 | T21: 0 | U21: 0 | V21: 4 | AA21: 0 | AB21: 42 | AE21: 0 | AF21: 1 | AI21: 0 | AJ21: 0
A24: DATA SASARAN KUNJUNGAN
A25: DESA | B25: =C3 -> : TEGAL YOSO
A26: TAHUN | B26: : 2025
A28: DATA SASARAN IBU HAMIL/NIFAS/MENYUSUI
A29: NO | B29: SASARAN IBU HAMIL/MENYUSUI | E29: JUMLAH KUNJUNGAN DAN JUMLAH SASARAN IBU HAMIL/NIFAS/MENYUSUI
B30: NAMA IBU | C30: NAMA SUAMI | D30: NAMA BAYI | E30: JAN | F30: FEB | G30: MAR | H30: APR | I30: MEI | J30: JUN | K30: JUL | L30: AGU | M30: SEP | N30: OKT | O30: NOV | P30: DES
A31: 1 | B31: 2 | C31: 3 | D31: 4 | E31: 5 | F31: 6 | G31: 7 | H31: 8 | I31: 9 | J31: 10 | K31: 11 | L31: 12 | M31: 13 | N31: 14 | O31: 15 | P31: 16
A32: 1 | B32: Rosmawati | C32: Asno | D32: Cheryl Nadzira Fayora
A33: 2 | B33: Nursyamsiah | C33: Pujiono | D33: Rayyanza Keivano Fauzi
A34: 3 | B34: Linda Kartinanda | C34: Dodi Prasetio | D34: Nahla Khalila
A35: 4 | B35: Deviana Nur Habibah | C35: Risky Ramadani | D35: Launa Felicia Putri
A36: 5 | B36: Munir | C36: Jaja Suhendar | D36: Ayyash Farhan Ramadhan
A37: 6 | B37: Maya Silvia | C37: Yoanda | D37: Kabay Nawarena Aretha
A38: 7 | B38: Dian Mardiana | C38: Ari Susanto | D38: Zayyan Akbar Ramadhan
A39: 8 | B39: Lilis Santi Umayah | C39: Paryadi | D39: Ahmad Adnan Toriq Alhafid
A40: 9 | B40: Susi Yanti | C40: Sugi Yanto | D40: M. Rafif Ahnaf Khavirunnas
A41: 10 | B41: Yun Farida | C41: Agus Triyana Putra | D41: Taqy Afaiz | K41: 1 | L41: 1 | M41: 1 | N41: 1 | O41: 1 | P41: 1
A42: 11 | B42: Nur Ayuni | C42: Didit Mulyana | D42: Athara Dayu Salsabilla | K42: 1 | L42: 1 | M42: 1 | N42: 1 | O42: 1 | P42: 1
A43: 12 | B43: Allfina Damayanti | C43: Ricky Endro | D43: Cio Adiwinata
A44: 13 | B44: Cucu Cahyanti | C44: Iwan Solihin | D44: Hafidzul Atmawijaya
...

Sheet KESEHATAN SIP 7
A1: DATA HASIL KEGIATAN
A4: NO | B4: BULAN | C4: IBU HAMIL | F4: JUMLAH IBU MENYUSUI | G4: JUMLAH AKSEPTOR | O4: PENIMBANGAN BALITA | AA4: IMUNISASI TT IBU HAMIL | AB4: JUMLAH BAYI YANG DIIMUNISASI | AZ4: BLITA YANG MENDERITA DIARE | BD4: KETERANGAN
C5: JUMLAH | D5: DIPERIKSA | E5: FE TAB (Tablet Besi) | G5: KONDOM | H5: PIL | I5: IMPLANT | J5: MOP | K5: MOW | L5: IUD | M5: SUNTIK | N5: LAIN-LAIN | O5: JML BALITA (S) | Q5: JML BALITA YANG MEMILIKI KMS (K) | S5: JML BALITA YANG DITIMBANG (D) | U5: JML BALTA YANG NAIK (N) | W5: JML BALITA YG MENDAPAT VIT. A | Y5: JML BALITA YG MENDAPATKAN PMT | AB5: BCG | AD5: DPT | AJ5: POLIO | AR5: CAMPAK | AT5: HEPATITIS B | AZ5: JUMLAH | BB5: YANG MENDAPATKAN ORALIT
A7: 1 | B7: 2 | C7: 3 | D7: 4 | E7: 5 | F7: 6 | G7: 7 | H7: 8 | I7: 9 | J7: 10 | K7: 11 | L7: 12 | M7: 13 | N7: 14 | O7: 15 | P7: 16 | Q7: 17 | R7: 18 | S7: 19 | T7: 20 | U7: 21 | V7: 22 | W7: 23 | X7: 24 | Y7: 25 | Z7: 26 | AA7: 27 | AB7: 28 | AC7: 29 | AD7: 30 | AE7: 31 | AF7: 32 | AG7: 33 | AH7: 34 | AI7: 35 | AJ7: 36 | AK7: 37 | AL7: 38 | AM7: 39 | AN7: 40 | AO7: 41 | AP7: 42 | AQ7: 43 | AR7: 44 | AS7: 45 | AT7: 46 | AU7: 47 | AV7: 48 | AW7: 49 | AX7: 50 | AY7: 51 | AZ7: 52 | BA7: 53 | BB7: 54 | BC7: 55 | BD7: 56
A8: 1 | B8: JANUARI
A9: 2 | B9: FEBRUARI
A10: 3 | B10: MARET
A11: 4 | B11: APRIL
A12: 5 | B12: MEI
A13: 6 | B13: JUNI
A14: 7 | B14: JULI
A15: 8 | B15: AGUSTUS
A16: 9 | B16: SEPTEMBER
A17: 10 | B17: OKTOBER
A18: 11 | B18: NOVEMBER
A19: 12 | B19: DESEMBER
A21: JUMLAH | C21: =SUM(C8:C19) -> 0 | D21: =SUM(D8:D19) -> 0 | E21: =SUM(E8:E19) -> 0 | F21: =SUM(F8:F19) -> 0 | G21: =SUM(G8:G19) -> 0 | H21: =SUM(H8:H19) -> 0 | I21: =SUM(I8:I19) -> 0 | J21: =SUM(J8:J19) -> 0 | ... BD21: =SUM(BD8:BD19) -> 0
A24: HASIL PEMERIKSAAN SASARAN
A27: REKAPITULASI IBU HAMIL/NIFAS/MENYUSUI
A28: Bulan/Tahun | B28: Ibu Hamil | C28: Ibu Menyusui | D28: Jumlah Sasaran | H28: Jumlah Ibu Hamil/Nifas/Menyusui dengan Hasil Penimbangan/Pengukuran/Pemeriksaan | O28: TTD | R28: PMT BUMIL KEK | U28: Jumlah Ibu Hamil Mengikuti Kelas | W28: Jumlah Ibu Nifas Mendapatkan Vit.A | Y28: Jumlah Ibu Nifas/Menyusui | AA28: Jumlah Ibu Hamil/Nifas/Menyusui | AB28: Jumlah Sasaran yang Dirujuk
D29: Datang | F29: Tidak Datang | H29: Berat Badan | J29: Lingkar Lengan Atas | L29: Tekanan Darah | N29: Gejala TBC | O29: Jumlah Ibu Hamil | P29: Ibu Hamil Konsumsi TTD | R29: Jumlah Ibu Hamil | S29: Ibu Hamil Konsumsi PMT | Y29: Mengikuti KB Pasca Persalinan | AA29: Mendapatkan Edukasi
D30: Ibu Hamil | E30: Ibu Menyusui | F30: Ibu Hamil | G30: Ibu Menyusui | H30: Hijau | I30: Merah | J30: Hijau | K30: Merah/KEK | L30: Hijau | M30: Merah | O30: Mendapatkan TTD | P30: Tiap Hari | Q30: Tidak | R30: Mendapatkan PMT | S30: Tiap Hari | T30: Tidak | U30: Ya | V30: Tidak | W30: Ya | X30: Tidak | Y30: Ya | Z30: Tidak | AB30: Ibu Hamil | AC30: Ibu Nifas/menyusui
A31: 1 | B31: 2 | C31: 3 | D31: 4 | E31: 5 | F31: 6 | G31: 7 | H31: 8 | I31: 9 | J31: 10 | K31: 11 | L31: 12 | M31: 13 | N31: 14 | O31: 15 | P31: 16 | Q31: 17 | R31: 18 | S31: 19 | T31: 20 | U31: 21 | V31: 22 | W31: 23 | X31: 24 | Y31: 25 | Z31: 26 | AA31: 27 | AB31: 28 | AC31: 29
A32: 45658
A33: 45689
A34: 45717
A35: 45748
A36: 45778
A37: 45809
A38: 45839
A39: 45870
A40: 45901
A41: 45931
A42: 45962
A43: 45992
A47: REKAPITULASI BAYI, BALITA DAN APRAS
A48: Bulan/Tahun | B48: Bayi | C48: Balita & Apras | D48: Jumlah Sasaran | H48: Jumlah Bayi/Balita/Apras dengan Hasil Penimbangan dan Pengukuran/Pemantauan/Pemeriksaan | W48: Jumlah Bayi dan Balita | AD48: Jumlah Balita Sakit | AE48: Jumlah Sasaran Dirujuk
B49: (0-6 bulan) | C49: (26 bulan - | D49: Datang | F49: Tidak Datang | H49: Balita dg Ceklis Perkembangan | J49: BB U(0-5 th) | N49: Hasil Pengukuran PB/TB/Umur 0-5 th | P49: Hasil Pengukuran BB/TP atau BB/TB | R49: Hasil Pengukuran Lingkar Kepala | T49: Lingkar Lengan Atas | V49: Gejala TBC | AE49: Bayi | AF49: Balita/Apras
C50: 6 Tahun) | D50: Bayi | E50: Balita | F50: Bayi | G50: Balita | H50: Lengkap | I50: Tidak Lengkap | J50: Naik | K50: Tidak Naik | L50: Gizi Baik | M50: Gizi Buruk | N50: Normal | O50: Tidak Normal | P50: Gizi Baik | Q50: Gizi Buruk | R50: Normal | S50: Tidak Normal | T50: Normal | U50: Tidak Normal | V50: 2 Gejala | W50: Asi Exclusive | X50: MP Asi | Y50: Imunisasi Bayi/Balita | Z50: Vit. A | AA50: Obat Cacing | AB50: MT Pangan Lokal | AC50: Edukasi | AE50: (0-6 bln) | AF50: (>=6 bln - 6 th)
A51: 1 | B51: 2 | C51: 3 | D51: 4 | E51: 5 | F51: 6 | G51: 7 | H51: 8 | I51: 9 | J51: 10 | K51: 11 | L51: 12 | M51: 13 | N51: 14 | O51: 15 | P51: 16 | Q51: 17 | R51: 18 | S51: 19 | T51: 20 | U51: 21 | V51: 22 | W51: 23 | X51: 24 | Y51: 25 | Z51: 26 | AA51: 27 | AB51: 28 | AC51: 29 | AD51: 30 | AE51: 31 | AF51: 32
...

Sheet PU
A1: LAPORAN POSYANDU
A2: BIDANG PEKERJAAN UMUM
B3: DESA | C3: =DATABASE!C2 -> : TEGAL YOSO
A5: No | B5: tanggal | C5: Nama Posyandu | D5: No Surat Permohonan RT | E5: Nama | F5: NIK | G5: Alamat | H5: Keluhan | I5: Lokasi Pembangunan Sarana | J5: Tindaklanjut
J6: TL | K6: BTL
A7: 1 | B7: 2 | C7: 3 | D7: 4 | E7: 5 | F7: 6 | G7: 7 | H7: 8 | I7: 9 | J7: 10 | K7: 11
A8: 1 | B8: 05 Juni 2025 | C8: =DATABASE!B6 -> Dahlia | D8: 04/SP.01/VI/25 | E8: DANI PRIATNA | F8: 3217061506680010 | G8: RT 04/25 | H8: MENGAJUKAN PEMBUATAN SUMUR BOR KARENA DIMUSIM KEMARAU KEKERINGAN | I8: LAPANG/TANAH KOSONG DEKAT RUMAH WARGA | J8: TELAH DIREALISASI DAPAT BANTUAN DARI ANGGOTA DEWAN (IBU NUR) PKS
A9: 2 | C9: =DATABASE!B7 -> Kenanga
A10: 3 | C10: =DATABASE!B8 -> Mawar
A11: 4 | C11: =DATABASE!B9 -> Melati
A12: 5 | C12: =DATABASE!B10 -> Anggrek
A13: 6 | C13: =DATABASE!B11 -> Cempaka

Sheet PR
A1: LAPORAN POSYANDU
A2: BIDANG PERUMAHAN RAKYAT
B3: DESA | C3: =DATABASE!C2 -> : TEGAL YOSO
A4: No | B4: tanggal | C4: Posyandu | D4: Nama | E4: NIK | F4: Alamat | G4: Persyaratan | L4: Tindaklanjut
G5: FC KK | H5: FC KTP | I5: SP* | J5: Suket Penghasilan | K5: Foto Kondisi Rumah | L5: TL | M5: BTL
A6: 1 | B6: 2 | C6: 3 | D6: 4 | E6: 5 | F6: 6 | G6: 7 | H6: 8 | I6: 9 | J6: 10 | K6: 11 | L6: 12 | M6: 13
A7: 1 | B7: 45753 | C7: =DATABASE!B6 -> Dahlia | D7: Apandi | E7: 3217061107690003 | F7: RT 12/25 | K7: Menepati tanah Developer karena belum memiliki rumah.
A8: 2 | C8: =DATABASE!B7 -> Kenanga
A9: 3 | C9: =DATABASE!B8 -> Mawar
A10: 4 | C10: =DATABASE!B9 -> Melati
A11: 5 | C11: =DATABASE!B10 -> Anggrek
A12: 6 | C12: =DATABASE!B11 -> Cempaka

Sheet TRANTIB LINMAS
A1: LAPORAN POSYANDU
A2: BIDANG TRANTIBUM LINMAS
B3: DESA | C3: ='KESEHATAN SIP 6'!B25 -> : TEGAL YOSO
A4: No | B4: tanggal | C4: Posyandu | D4: NIK | E4: Nama | F4: Alamat | G4: Hal pengaduan | H4: Keterangan
H5: TL | I5: BTL
A6: 1 | B6: 2 | D6: 3 | E6: 4 | F6: 5 | G6: 6 | H6: 7 | I6: 8
A7: 1 | B7: 02 Juni 2025 | C7: =DATABASE!B6 -> Dahlia | D7: 3217060105770092 | E7: Indianto | F7: RT 03 RW 25 | G7: Kehilangan 2 unit motor | H7: Lapor ke Polisi
A8: 2 | C8: =DATABASE!B7 -> Kenanga
A9: 3 | C9: =DATABASE!B8 -> Mawar
A10: 4 | C10: =DATABASE!B9 -> Melati
A11: 5 | C11: =DATABASE!B10 -> Anggrek
A12: 6 | C12: =DATABASE!B11 -> Cempaka

Sheet SOSIAL
A1: LAPORAN POSYANDU
A2: BIDANG SOSIAL
A3: DESA | B3: ='TRANTIB LINMAS'!C3 -> : TEGAL YOSO
A5: No | B5: tanggal | C5: Posyandu | D5: NIK | E5: Nama | F5: Alamat | G5: Hal pengaduan | H5: Keterangan
H6: TL | I6: BTL
A7: 1 | B7: 2 | C7: 3 | D7: 4 | E7: 5 | F7: 6 | G7: 7 | H7: 8 | I7: 9
A8: 1 | B8: 20 Juli 2025 | C8: =DATABASE!B6 -> Dahlia | D8: 3217060812490003 | E8: SAFEI | F8: RT 08/25 | G8: PENGAJUAN KIS | H8: LANGSUNG DI AJUKAN DAN DISETUJUI
A9: 2 | C9: =DATABASE!B7 -> Kenanga
A10: 3 | C10: =DATABASE!B8 -> Mawar
A11: 4 | C11: =DATABASE!B9 -> Melati
A12: 5 | C12: =DATABASE!B10 -> Anggrek
A13: 6 | C13: =DATABASE!B11 -> Cempaka
