Workbook

Sheet DATABASE
A1: DATABASE POSYANDU
B2: DESA
A4: NO | B4: NAMA POSYANDU | C4: HARI BUKA | D4: JUMLAH RUMAH | E4: JUMLAH KK | F4: JUMLAH PENDUDUK | H4: JUMLAH ANAK USIA 3-6 THN | I4: JUMLAH ANAK USIA SD | J4: JUMLAH USIA PRODUKTIF | L4: JUMLAH LANSIA | M4: JUMLAH DISABILITAS | N4: STATUS BANGUNAN POSYANDU | P4: DANA SEHAT | R4: JUMLAH KADER | S4: STRATA POSYANDU | T4: KEGIATAN INTEGRASI
F5: L | G5: P | J5: PUS | K5: WUS | N5: MILIK SENDIRI | O5: MENUMPANG | P5: ADA | Q5: TIDAK ADA
A6: 1 | B6: MAWAR | C6: Tanggal 8 | D6: 137 | E6: 137 | F6: 201 | G6: 210 | H6: ='KES SIP 6 MAWAR'!A99 -> 16 | I6: ='KES SIP 6 MAWAR'!A157 -> 52 | J6: 66 | K6: 105 | L6: 67 | M6: 0 | N6: 0 | O6: 1 | P6: 0 | Q6: 0 | R6: 7 | S6: Madya
A7: 2 | B7: KENANGA | C7: Tanggal 5 | D7: 186 | E7: 186 | F7: 229 | G7: 262 | H7: ='KES SIP 6 KENANGA'!A130 -> 38 | I7: ='KES SIP 6 KENANGA'!A234 -> 87 | J7: 90 | K7: 157 | L7: 76 | M7: 5 | N7: 0 | O7: 1 | P7: 0 | Q7: 0 | R7: 7 | S7: Madya
A8: 3 | B8: DAHLIA | C8: Tanggal 11 | D8: 281 | E8: 281 | F8: 339 | G8: 408 | H8: ='KES SIP 6 DAHLIA'!A142 -> 31 | I8: ='KES SIP 6 DAHLIA'!A174 -> 26 | J8: 137 | K8: 76 | L8: 65 | M8: 0 | N8: 0 | O8: 1 | P8: 0 | Q8: 0 | R8: 7 | S8: Madya
A9: 4 | B9: MELATI | C9: Tanggal 12 | D9: 231 | E9: 231 | F9: 267 | G9: 334 | H9: ='KES SIP 6 MELATI'!A123 -> 23 | I9: ='KES SIP 6 MELATI'!A203 -> 70 | J9: 126 | K9: 173 | L9: 60 | M9: 2 | N9: 0 | O9: 1 | P9: 0 | Q9: 0 | R9: 7 | S9: Madya
A10: JUMLAH | D10: =SUM(D6:D9) -> 835 | E10: =SUM(E6:E9) -> 835 | F10: =SUM(F6:F9) -> 1036 | G10: =SUM(G6:G9) -> 1214 | H10: =SUM(H6:H9) -> 108 | I10: =SUM(I6:I9) -> 235 | J10: =SUM(J6:J9) -> 419 | K10: =SUM(K6:K9) -> 511 | ... T10: =SUM(T6:T9) -> 0

Sheet PENDIDIKAN
A1: LAPORAN POSYANDU
A2: BIDANG PENDIDIKAN
B3: DESA
A5: No | B5: tanggal | C5: Posyandu | D5: NIK | E5: Nama | F5: Alamat | G5: Hal pengaduan | H5: Keterangan
H6: TL | I6: BTL
A7: 1 | B7: 2 | C7: 3 | D7: 4 | E7: 5 | F7: 6 | G7: 7 | H7: 8 | I7: 9
A8: 1 | B8: 16-06-2025 | C8: CONTOH1 | D8: 3217064006750012 | E8: YANTI NURHAYATI | F8: RT 10/25 | G8: Tidak ada biaya untuk Kuliah jadi mengajukan pembuatan KIP | H8: Sudah diproses | I8: -
A9: 2
A10: 3

Sheet KES SIP 6 MAWAR
A1: DATA PENGUNJUNG
C3: DESA : BUMI MAS
A4: NO | C4: BULAN | D4: JUMLAH PENGUNJUNG | AC4: JUMLAH PETUGAS YG HADIR | AI4: JUMLAH BAYI | AM4: KET
D5: B A L I T A | M5: ANAK USIA 6-15 TAHUN | Q5: USIA PRODUKTIF | U5: LANSIA | Y5: WUS | Z5: IBU | AC5: KADER | AE5: PLKB | AG5: MEDIS DAN PARA MEDIS | AI5: YANG LAHIR | AK5: MENINGGAL
D6: BAYI 0 - 12 BULAN | I6: BALITA 1-5 TAHUN | Z6: PUS | AA6: HAMIL | AB6: MENYUSUI
D7: BARU | F7: LAMA | H7: TOTAL | I7: BARU | K7: LAMA | M7: BARU | O7: LAMA | Q7: BARU | S7: LAMA | U7: BARU | W7: LAMA
D8: L | E8: P | F8: L | G8: P | I8: L | J8: P | K8: L | L8: P | M8: L | N8: P | O8: L | P8: P | Q8: L | R8: P | S8: L | T8: P | U8: L | V8: P | W8: L | X8: P | AC8: L | AD8: P | AE8: L | AF8: P | AG8: L | AH8: P | AI8: L | AJ8: P | AK8: L | AL8: P
A9: 1 | C9: 2 | D9: 3 | E9: 4 | F9: 5 | G9: 6 | I9: 7 | J9: 8 | K9: 9 | L9: 10 | M9: 11 | N9: 12 | O9: 13 | P9: 14 | Q9: 15 | R9: 16 | S9: 17 | T9: 18 | U9: 19 | V9: 20 | W9: 21 | X9: 22 | Y9: 23 | Z9: 24 | AA9: 25 | AB9: 26 | AC9: 27 | AD9: 28 | AE9: 29 | AF9: 30 | AG9: 31 | AH9: 32 | AI9: 33 | AJ9: 34 | AK9: 35 | AL9: 36 | AM9: 37
A10: 1 | C10: JANUARI | D10: 0 | E10: 0 | F10: =SUM(I51,I53,I57) -> 0 | G10: =SUM(I52,I54,I55,I56) -> 2 | H10: =SUM(D10:G10) -> 2 | I10: 0 | J10: =sum(I94) -> 1 | K10: =sum(I66,I68,I69,I75,I80,I81,I85,I87,I88,I91,I93) -> 6 | L10: =sum(I65,I67,I69,I70,I71,I72,I73,I74,I76,I77,I78,I79,I82,I83,I84,I86,I89,I90,I92,I94,I95,I96,I97,I98,I99) -> 9 | M10: =Sum(I173) -> 0 | N10: =sum(I174) -> 0 | O10: =SUM(I107,I108,I110,I111,I112,I113,I114,I117,I118,I120,I122,I124,I125,I130,I131,I132,I133,I139,I142,I144,I148,I149,I150,I153,I155,I156,I157,I159,I161,I163,I164,I166,I167,I169,I172) -> 14 | P10: =SUM(I106,I109,I115,I116,I119,I121,I123,I126,I127,I128,I129,I134,I135,I136,I137,I138,I140,I141,I143,I145,I146,I147,I151,I152,I154,I158,I160,I162,I165,I168,I170,I171) -> 15
A11: 2 | C11: FEBRUARI | D11: 0 | E11: 0 | F11: =SUM(J51,J53,J57) -> 0 | G11: =SUM(J52,J54,J55,J56) -> 2 | H11: =SUM(D11:G11) -> 2 | I11: 0 | J11: 0 | K11: =sum(J66,J68,J69,J75,J80,J81,J85,J87,J88,J91,J93) -> 6 | L11: =sum(J65,J67,J69,J70,J71,J72,J73,J74,J76,J77,J78,J79,J82,J83,J84,J86,J89,J90,J92,J94,J95,J96,J97,J98,J99) -> 8 | M11: 0 | N11: 0 | O11: =SUM(J107,J108,J110,J111,J112,J113,J114,J117,J118,J120,J122,J124,J125,J130,J131,J132,J133,J139,J142,J144,J148,J149,J150,J153,J155,J156,J157,J159,J161,J163,J164,J166,J167,J169,J172,J173) -> 12 | P11: =SUM(J106,J109,J115,J116,J119,J121,J123,J126,J127,J128,J129,J134,J135,J136,J137,J138,J140,J141,J143,J145,J146,J147,J151,J152,J154,J158,J160,J162,J165,J168,J170,J171,J174) -> 8
A12: 3 | C12: MARET | D12: =SUM(K51) -> 0 | E12: 0 | F12: =SUM(K53,K57) -> 0 | G12: =SUM(K52,K54,K55,K56) -> 2 | H12: =SUM(D12:G12) -> 2 | I12: 0 | J12: 0 | K12: =sum(K66,K68,K69,K75,K80,K81,K85,K87,K88,K91,K93) -> 4 | L12: =sum(K65,K67,K69,K70,K71,K72,K73,K74,K76,K77,K78,K79,K82,K83,K84,K86,K89,K90,K92,K94,K95,K96,K97,K98,K99) -> 6 | M12: 0 | N12: 0 | O12: =SUM(K107,K108,K110,K111,K112,K113,K114,K117,K118,K120,K122,K124,K125,K130,K131,K132,K133,K139,K142,K144,K148,K149,K150,K153,K155,K156,K157,K159,K161,K163,K164,K166,K167,K169,K172,K173) -> 4 | P12: =SUM(K106,K109,K115,K116,K119,K121,K123,K126,K127,K128,K129,K134,K135,K136,K137,K138,K140,K141,K143,K145,K146,K147,K151,K152,K154,K158,K160,K162,K165,K168,K170,K171,K174) -> 4
A13: 4 | C13: APRIL | D13: =SUM(L53) -> 0 | E13: =SUM(L52,L54) -> 0 | F13: =SUM(L51) -> 0 | G13: =SUM(L55,L56) -> 2 | H13: =SUM(D13:G13) -> 2 | I13: 0 | J13: 0 | K13: =sum(L66,L68,L69,L75,L80,L81,L85,L87,L88,L91,L93) -> 4 | L13: =sum(L65,L67,L69,L70,L71,L72,L73,L74,L76,L77,L78,L79,L82,L83,L84,L86,L89,L90,L92,L94,L95,L96,L97,L98,L99) -> 6 | M13: 0 | N13: =sum(L175) -> 0 | O13: =SUM(L107,L108,L110,L111,L112,L113,L114,L117,L118,L120,L122,L124,L125,L130,L131,L132,L133,L139,L142,L144,L148,L149,L150,L153,L155,L156,L157,L159,L161,L163,L164,L166,L167,L169,L172,L173) -> 10 | P13: =SUM(L106,L109,L115,L116,L119,L121,L123,L126,L127,L128,L129,L134,L135,L136,L137,L138,L140,L141,L143,L145,L146,L147,L151,L152,L154,L158,L160,L162,L165,L168,L170,L171,L174) -> 7
A14: 5 | C14: MEI | D14: 0 | E14: 0 | F14: =SUM(M51,M53,M57) -> 0 | G14: =SUM(M52,M54,M55,M56) -> 2 | H14: =SUM(D14:G14) -> 2 | I14: 0 | J14: =sum(M95,M96) -> 0 | K14: =sum(M66,M68,M69,M75,M80,M81,M85,M87,M88,M91,M93) -> 5 | L14: =sum(M65,M67,M69,M70,M71,M72,M73,M74,M76,M77,M78,M79,M82,M83,M84,M86,M89,M90,M92,M94,M95,M96,M97,M98,M99) -> 8 | M14: =Sum(M176,M177) -> 0 | N14: 0 | O14: =SUM(M107,M108,M110,M111,M112,M113,M114,M117,M118,M120,M122,M124,M125,M130,M131,M132,M133,M139,M142,M144,M148,M149,M150,M153,M155,M156,M157,M159,M161,M163,M164,M166,M167,M169,M172,M173) -> 14 | P14: =SUM(M106,M109,M115,M116,M119,M121,M123,M126,M127,M128,M129,M134,M135,M136,M137,M138,M140,M141,M143,M145,M146,M147,M151,M152,M154,M158,M160,M162,M165,M168,M170,M171,M174,M175) -> 5
A15: 6 | C15: JUNI | D15: 0 | E15: =SUM(N55) -> 1 | F15: =SUM(N51,N53,N57) -> 1 | G15: =SUM(N52,N54,N56) -> 2 | H15: =SUM(D15:G15) -> 4 | I15: 0 | J15: 0 | K15: =sum(N66,N68,N69,N75,N80,N81,N85,N87,N88,N91,N93) -> 4 | L15: =sum(N65,N67,N69,N70,N71,N72,N73,N74,N76,N77,N78,N79,N82,N83,N84,N86,N89,N90,N92,N94,N95,N96,N97,N98,N99) -> 9 | M15: =sum(N178) -> 0 | N15: 0 | O15: =SUM(N107,N108,N110,N111,N112,N113,N114,N117,N118,N120,N122,N124,N125,N130,N131,N132,N133,N139,N142,N144,N148,N149,N150,N153,N155,N156,N157,N159,N161,N163,N164,N166,N167,N169,N172,N173,N176,N177) -> 7 | P15: =SUM(N106,N109,N115,N116,N119,N121,N123,N126,N127,N128,N129,N134,N135,N136,N137,N138,N140,N141,N143,N145,N146,N147,N151,N152,N154,N158,N160,N162,N165,N168,N170,N171,N174,N175) -> 9
A16: 7 | C16: JULI | D16: 0 | E16: =SUM(O56) -> 1 | F16: =SUM(O51,O53,O57) -> 1 | G16: =SUM(O52,O54,O55) -> 2 | H16: =SUM(D16:G16) -> 4 | I16: 0 | J16: =sum(O97) -> 1 | K16: =sum(O66,O68,O69,O75,O80,O81,O85,O87,O88,O91,O93) -> 6 | L16: =sum(O65,O67,O69,O70,O71,O72,O73,O74,O76,O77,O78,O79,O82,O83,O84,O86,O89,O90,O92,O94,O95,O96,O97,O98,O99) -> 10 | M16: 0 | N16: 0 | O16: =SUM(O107,O108,O110,O111,O112,O113,O114,O117,O118,O120,O122,O124,O125,O130,O131,O132,O133,O139,O142,O144,O148,O149,O150,O153,O155,O156,O157,O159,O161,O163,O164,O166,O167,O169,O172,O173,O176,O177,O178) -> 10 | P16: =SUM(O106,O109,O115,O116,O119,O121,O123,O126,O127,O128,O129,O134,O135,O136,O137,O138,O140,O141,O143,O145,O146,O147,O151,O152,O154,O158,O160,O162,O165,O168,O170,O171,O174,O175) -> 8
A17: 8 | C17: AGUSTUS | D17: 0 | E17: 0 | F17: =SUM(P51,P53,P57) -> 1 | G17: =SUM(P52,P54,P55,P56) -> 3 | H17: =SUM(D17:G17) -> 4 | I17: 0 | J17: 0 | K17: =SUM(P66,P68,P69,P75,P80,P81,P85,P87,P88,P91,P93) -> 5 | L17: =suM(P65,P67,P69,P70,P71,P72,P73,P74,P76,P77,P78,P79,P82,P83,P84,P86,P89,P90,P92,P94,P95,P96,P97,P98,P99) -> 8 | M17: 0 | N17: 0 | O17: =SUM(P107,P108,P110,P111,P112,P113,P114,P117,P118,P120,P122,P124,P125,P130,P131,P132,P133,P139,P142,P144,P148,P149,P150,P153,P155,P156,P157,P159,P161,P163,P164,P166,P167,P169,P172,P173,P176,P177,P178) -> 8 | P17: =SUM(P106,P109,P115,P116,P119,P121,P123,P126,P127,P128,P129,P134,P135,P136,P137,P138,P140,P141,P143,P145,P146,P147,P151,P152,P154,P158,P160,P162,P165,P168,P170,P171,P174,P175) -> 11
A18: 9 | C18: SEPTEMBER | D18: =SUM(Q57) -> 0 | E18: 0 | F18: =SUM(Q51,Q53) -> 1 | G18: =SUM(Q52,Q54,Q55,Q56) -> 3 | H18: =SUM(D18:G18) -> 4 | I18: 0 | J18: =sum(Q98) -> 1 | K18: =suM(Q66,Q68,Q69,Q75,Q80,Q81,Q85,Q87,Q88,Q91,Q93) -> 5 | L18: =suM(Q65,Q67,Q69,Q70,Q71,Q72,Q73,Q74,Q76,Q77,Q78,Q79,Q82,Q83,Q84,Q86,Q89,Q90,Q92,Q94,Q95,Q96,Q97,Q98,Q99) -> 10 | M18: 0 | N18: 0 | O18: =SUM(Q107,Q108,Q110,Q111,Q112,Q113,Q114,Q117,Q118,Q120,Q122,Q124,Q125,Q130,Q131,Q132,Q133,Q139,Q142,Q144,Q148,Q149,Q150,Q153,Q155,Q156,Q157,Q159,Q161,Q163,Q164,Q166,Q167,Q169,Q172,Q173,Q176,Q177,Q178) -> 7 | P18: =SUM(Q106,Q109,Q115,Q116,Q119,Q121,Q123,Q126,Q127,Q128,Q129,Q134,Q135,Q136,Q137,Q138,Q140,Q141,Q143,Q145,Q146,Q147,Q151,Q152,Q154,Q158,Q160,Q162,Q165,Q168,Q170,Q171,Q174,Q175) -> 11
A19: 10 | C19: OKTOBER | D19: 0 | E19: 0 | F19: =SUM(R51,R53,R57) -> 1 | G19: =SUM(R52,R54,R55,R56) -> 3 | H19: =SUM(D19:G19) -> 4 | I19: 0 | J19: 0 | K19: =suM(R66,R68,R69,R75,R80,R81,R85,R87,R88,R91,R93) -> 7 | L19: =suM(R65,R67,R69,R70,R71,R72,R73,R74,R76,R77,R78,R79,R82,R83,R84,R86,R89,R90,R92,R94,R95,R96,R97,R98,R99) -> 11 | M19: 0 | N19: =SUM(R179) -> 0 | O19: =SUM(R107,R108,R110,R111,R112,R113,R114,R117,R118,R120,R122,R124,R125,R130,R131,R132,R133,R139,R142,R144,R148,R149,R150,R153,R155,R156,R157,R159,R161,R163,R164,R166,R167,R169,R172,R173,R176,R177,R178) -> 12 | P19: =SUM(R106,R109,R115,R116,R119,R121,R123,R126,R127,R128,R129,R134,R135,R136,R137,R138,R140,R141,R143,R145,R146,R147,R151,R152,R154,R158,R160,R162,R165,R168,R170,R171,R174,R175) -> 4
A20: 11 | C20: NOVEMBER | D20: 0 | E20: 0 | F20: =SUM(S51,S53,S57) -> 1 | G20: =SUM(S52,S54,S55,S56) -> 4 | H20: =SUM(D20:G20) -> 5 | I20: 0 | J20: =sum(S99) -> 1 | K20: =suM(S66,S68,S69,S75,S80,S81,S85,S87,S88,S91,S93) -> 7 | L20: =suM(S65,S67,S69,S70,S71,S72,S73,S74,S76,S77,S78,S79,S82,S83,S84,S86,S89,S90,S92,S94,S95,S96,S97,S98,S99) -> 12 | M20: 0 | N20: =SUM(S180) -> 0 | O20: =SUM(S107,S108,S110,S111,S112,S113,S114,S117,S118,S120,S122,S124,S125,S130,S131,S132,S133,S139,S142,S144,S148,S149,S150,S153,S155,S156,S157,S159,S161,S163,S164,S166,S167,S169,S172,S173,S176,S177,S178) -> 9 | P20: =SUM(S106,S109,S115,S116,S119,S121,S123,S126,S127,S128,S129,S134,S135,S136,S137,S138,S140,S141,S143,S145,S146,S147,S151,S152,S154,S158,S160,S162,S165,S168,S170,S171,S174,S175,S179) -> 5
A21: 12 | C21: DESEMBER | D21: 0 | E21: 0 | F21: =SUM(T51,T53,T57) -> 2 | G21: =SUM(T52,T54,T55,T56) -> 4 | H21: =SUM(D21:G21) -> 6 | I21: 0 | J21: 0 | K21: =suM(T66,T68,T69,T75,T80,T81,T85,T87,T88,T91,T93) -> 6 | L21: =suM(T65,T67,T69,T70,T71,T72,T73,T74,T76,T77,T78,T79,T82,T83,T84,T86,T89,T90,T92,T94,T95,T96,T97,T98,T99) -> 9 | M21: 0 | N21: =SUM(T181) -> 0 | O21: =SUM(T107,T108,T110,T111,T112,T113,T114,T117,T118,T120,T122,T124,T125,T130,T131,T132,T133,T139,T142,T144,T148,T149,T150,T153,T155,T156,T157,T159,T161,T163,T164,T166,T167,T169,T172,T173,T176,T177,T178) -> 11 | P21: =SUM(T106,T109,T115,T116,T119,T121,T123,T126,T127,T128,T129,T134,T135,T136,T137,T138,T140,T141,T143,T145,T146,T147,T151,T152,T154,T158,T160,T162,T165,T168,T170,T171,T174,T175,T179,T180) -> 11
C22: TOTAL | D22: =SUM(D10:D21) -> 0 | E22: =SUM(E10:E21) -> 2 | F22: =SUM(F10:F21) -> 8 | G22: =SUM(G10:G21) -> 31 | H22: =SUM(H10:H21) -> 41 | I22: =SUM(I10:I21) -> 0 | J22: =SUM(J10:J21) -> 4 | K22: =SUM(K10:K21) -> 65 | ... P22: =SUM(P10:P21) -> 98
A24: DATA SASARAN KUNJUNGAN
A25: DESA : | C25: BUMI MAS
A26: TAHUN : | C26: 2025
A28: DATA SASARAN IBU HAMIL/NIFAS/MENYUSUI
A29: NO | C29: SASARAN IBU HAMIL/MENYUSUI | F29: TANGGAL LAHIR | G29: JUMLAH KUNJUNGAN DAN JUMLAH SASARAN IBU HAMIL/NIFAS/MENYUSUI
C30: NAMA IBU | D30: NAMA SUAMI | E30: NAMA BAYI | G30: JAN | H30: FEB | I30: MAR | J30: APR | K30: MEI | L30: JUN | M30: JUL | N30: AGU | O30: SEP | P30: OKT | Q30: NOV | R30: DES | S30: JUMLAH
A31: 1 | C31: 2 | D31: 3 | E31: 4 | G31: 5 | H31: 6 | I31: 7 | J31: 8 | K31: 9 | L31: 10 | M31: 11 | N31: 12 | O31: 13 | P31: 14 | Q31: 15 | R31: 16
A32: 1 | C32: Tika Mayasari | D32: Romadona Catur | E32: Fahel Tristian Daneswara | F32: 35260 | G32: 0 | H32: 0 | I32: 0 | J32: 0 | K32: 0 | L32: 0 | M32: 0 | N32: 0 | O32: 0 | P32: 1 | Q32: 1 | R32: 0 | S32: =SUM(G32:R32) -> 2
A33: =A32+1 -> 2 | C33: Ani Kholifatunnisa | D33: Edi Julianto | E33: Elshinta Khodijah | F33: 35215 | G33: 0 | H33: 0 | I33: 0 | J33: 0 | K33: 1 | L33: 0 | M33: 1 | N33: 1 | O33: 0 | Q33: 1 | R33: 1 | S33: =SUM(G33:R33) -> 5
A34: =A33+1 -> 3 | C34: Indri Eka Saputri | D34: Sugiarto | E34: Anya Sabrina Naviera | F34: 34221 | G34: 1 | H34: 1 | I34: 1 | J34: 1 | K34: 1 | L34: 1 | M34: 1 | N34: 1 | O34: 1 | P34: 1 | Q34: 1 | R34: 1 | S34: =SUM(G34:R34) -> 12
A35: =A34+1 -> 4 | C35: Dinda Yulia Krisma | D35: Afrizal Fahri | E35: Muhammad ElZavier Aswindra | F35: 36003 | G35: 0 | H35: 0 | I35: 0 | J35: 1 | K35: 1 | L35: 1 | M35: 1 | N35: 0 | O35: 1 | P35: 1 | Q35: 1 | R35: 1 | S35: =SUM(G35:R35) -> 8
A36: =A35+1 -> 5 | C36: Neliyana Lasmita | D36: Elga Erlangga | E36: - | F36: 37488 | G36: 0 | H36: 0 | I36: 0 | J36: 0 | K36: 0 | L36: 0 | M36: 0 | N36: 0 | O36: 1 | P36: 1 | Q36: 1 | R36: 1 | S36: =SUM(G36:R36) -> 4
A37: =A36+1 -> 6 | S37: =SUM(G37:R37) -> 0
A38: =A37+1 -> 7 | S38: =SUM(G38:R38) -> 0
A40: =A38+1 -> 8 | S40: =SUM(G40:R40) -> 0
A41: JUMLAH | G41: =SUM(G32:G40) -> 1 | H41: =SUM(H32:H40) -> 1 | I41: =SUM(I32:I40) -> 1 | J41: =SUM(J32:J40) -> 2 | K41: =SUM(K32:K40) -> 3 | L41: =SUM(L32:L40) -> 2 | M41: =SUM(M32:M40) -> 3 | N41: =SUM(N32:N40) -> 2 | ... S41: =SUM(S32:S40) -> 31
A47: DATA SASARAN BAYI (0-12 BULAN)
A48: NO | C48: NAMA BAYI/BALITA | D48: JENIS KELAMIN | E48: TANGGAL LAHIR | F48: USIA | G48: NAMA | I48: JUMLAH KUNJUNGAN DAN JUMLAH SASARAN BALITA BAYI 0-12 BULAN
G49: IBU | H49: AYAH | I49: JAN | J49: FEB | K49: MAR | L49: APR | M49: MEI | N49: JUN | O49: JUL | P49: AGU | Q49: SEP | R49: OKT | S49: NOV | T49: DES | U49: JUMLAH
...

Sheet KES SIP 6 KENANGA
A1: DATA PENGUNJUNG
B3: DESA : BUMI MAS
A4: NO | B4: BULAN | F4: JUMLAH PENGUNJUNG | AF4: JUMLAH PETUGAS YG HADIR | AL4: JUMLAH BAYI | AP4: KET
F5: B A L I T A | P5: ANAK USIA 6-15 TAHUN | T5: USIA PRODUKTIF | X5: LANSIA | AB5: WUS | AC5: IBU | AF5: KADER | AH5: PLKB | AJ5: MEDIS DAN PARA MEDIS | AL5: YANG LAHIR | AN5: MENINGGAL
F6: BAYI 0 - 12 BULAN | L6: BALITA 1-5 TAHUN | AC6: PUS | AD6: HAMIL | AE6: MENYUSUI
F7: BARU | I7: LAMA | K7: TOTAL | L7: BARU | N7: LAMA | P7: BARU | R7: LAMA | T7: BARU | V7: LAMA | X7: BARU | Z7: LAMA
F8: L | G8: P | I8: L | J8: P | L8: L | M8: P | N8: L | O8: P | P8: L | Q8: P | R8: L | S8: P | T8: L | U8: P | V8: L | W8: P | X8: L | Y8: P | Z8: L | AA8: P | AF8: L | AG8: P | AH8: L | AI8: P | AJ8: L | AK8: P | AL8: L | AM8: P | AN8: L | AO8: P
A9: 1 | B9: 2 | F9: 3 | G9: 4 | I9: 5 | J9: 6 | L9: 7 | M9: 8 | N9: 9 | O9: 10 | P9: 11 | Q9: 12 | R9: 13 | S9: 14 | T9: 15 | U9: 16 | V9: 17 | W9: 18 | X9: 19 | Y9: 20 | Z9: 21 | AA9: 22 | AB9: 23 | AC9: 24 | AD9: 25 | AE9: 26 | AF9: 27 | AG9: 28 | AH9: 29 | AI9: 30 | AJ9: 31 | AK9: 32 | AL9: 33 | AM9: 34 | AN9: 35 | AO9: 36 | AP9: 37
A10: 1 | B10: JANUARI | F10: 0 | G10: 0 | I10: =SUM(L50,L52,L56) -> 0 | J10: =SUM(L51,L53,L54,L55) -> 0 | K10: =SUM(F10:J10) -> 0 | L10: 0 | M10: =sum(L123) -> 0 | N10: =sum(L93,L95,L96,L103,L108,L109,L114,L116,L117,L120,L122) -> 7 | O10: =sum(L92,L94,L96,L97,L98,L99,L100,L101,L104,L105,L106,L107,L110,L112,L113,L115,L118,L119,L121,L123,L124,L125,L126,L127,L128) -> 15 | P10: =Sum(L215) -> 0 | Q10: =sum(L216) -> 0 | R10: =SUM(L149,L150,L152,L153,L154,L155,L156,L159,L160,L162,L164,L166,L167,L172,L173,L174,L175,L181,L184,L186,L190,L191,L192,L195,L197,L198,L199,L201,L203,L205,L206,L208,L209,L211,L214) -> 0 | S10: =SUM(L148,L151,L157,L158,L161,L163,L165,L168,L169,L170,L171,L176,L177,L178,L179,L180,L182,L183,L185,L187,L188,L189,L193,L194,L196,L200,L202,L204,L207,L210,L212,L213) -> 0
A11: 2 | B11: FEBRUARI | F11: 0 | G11: 0 | I11: =SUM(M50,M52,M56) -> 0 | J11: =SUM(M51,M53,M54,M55) -> 0 | K11: =SUM(F11:J11) -> 0 | L11: 0 | M11: 0 | N11: =sum(M93,M95,M96,M103,M108,M109,M114,M116,M117,M120,M122) -> 6 | O11: =sum(M92,M94,M96,M97,M98,M99,M100,M101,M104,M105,M106,M107,M110,M112,M113,M115,M118,M119,M121,M123,M124,M125,M126,M127,M128) -> 16 | P11: 0 | Q11: 0 | R11: =SUM(M149,M150,M152,M153,M154,M155,M156,M159,M160,M162,M164,M166,M167,M172,M173,M174,M175,M181,M184,M186,M190,M191,M192,M195,M197,M198,M199,M201,M203,M205,M206,M208,M209,M211,M214,M215) -> 0 | S11: =SUM(M148,M151,M157,M158,M161,M163,M165,M168,M169,M170,M171,M176,M177,M178,M179,M180,M182,M183,M185,M187,M188,M189,M193,M194,M196,M200,M202,M204,M207,M210,M212,M213,M216) -> 0
A12: 3 | B12: MARET | F12: =SUM(N50) -> 0 | G12: 0 | I12: =SUM(N52,N56) -> 0 | J12: =SUM(N51,N53,N54,N55) -> 0 | K12: =SUM(F12:J12) -> 0 | L12: 0 | M12: 0 | N12: =sum(N93,N95,N96,N103,N108,N109,N114,N116,N117,N120,N122) -> 8 | O12: =sum(N92,N94,N96,N97,N98,N99,N100,N101,N104,N105,N106,N107,N110,N112,N113,N115,N118,N119,N121,N123,N124,N125,N126,N127,N128) -> 15 | P12: 0 | Q12: 0 | R12: =SUM(N149,N150,N152,N153,N154,N155,N156,N159,N160,N162,N164,N166,N167,N172,N173,N174,N175,N181,N184,N186,N190,N191,N192,N195,N197,N198,N199,N201,N203,N205,N206,N208,N209,N211,N214,N215) -> 0 | S12: =SUM(N148,N151,N157,N158,N161,N163,N165,N168,N169,N170,N171,N176,N177,N178,N179,N180,N182,N183,N185,N187,N188,N189,N193,N194,N196,N200,N202,N204,N207,N210,N212,N213,N216) -> 0
A13: 4 | B13: APRIL | F13: =SUM(O52) -> 0 | G13: =SUM(O51,O53) -> 0 | I13: =SUM(O50) -> 0 | J13: =SUM(O54,O55) -> 0 | K13: =SUM(F13:J13) -> 0 | L13: 0 | M13: 0 | N13: =sum(O93,O95,O96,O103,O108,O109,O114,O116,O117,O120,O122) -> 9 | O13: =sum(O92,O94,O96,O97,O98,O99,O100,O101,O104,O105,O106,O107,O110,O112,O113,O115,O118,O119,O121,O123,O124,O125,O126,O127,O128) -> 14 | P13: 0 | Q13: =sum(O217) -> 0 | R13: =SUM(O149,O150,O152,O153,O154,O155,O156,O159,O160,O162,O164,O166,O167,O172,O173,O174,O175,O181,O184,O186,O190,O191,O192,O195,O197,O198,O199,O201,O203,O205,O206,O208,O209,O211,O214,O215) -> 0 | S13: =SUM(O148,O151,O157,O158,O161,O163,O165,O168,O169,O170,O171,O176,O177,O178,O179,O180,O182,O183,O185,O187,O188,O189,O193,O194,O196,O200,O202,O204,O207,O210,O212,O213,O216) -> 0
A14: 5 | B14: MEI | F14: 0 | G14: 0 | I14: =SUM(P50,P52,P56) -> 1 | J14: =SUM(P51,P53,P54,P55) -> 0 | K14: =SUM(F14:J14) -> 1 | L14: 0 | M14: =sum(P124,P125) -> 1 | N14: =sum(P93,P95,P96,P103,P108,P109,P114,P116,P117,P120,P122) -> 10 | O14: =sum(P92,P94,P96,P97,P98,P99,P100,P101,P104,P105,P106,P107,P110,P112,P113,P115,P118,P119,P121,P123,P124,P125,P126,P127,P128) -> 17 | P14: =Sum(P218,P219) -> 0 | Q14: 0 | R14: =SUM(P149,P150,P152,P153,P154,P155,P156,P159,P160,P162,P164,P166,P167,P172,P173,P174,P175,P181,P184,P186,P190,P191,P192,P195,P197,P198,P199,P201,P203,P205,P206,P208,P209,P211,P214,P215) -> 0 | S14: =SUM(P148,P151,P157,P158,P161,P163,P165,P168,P169,P170,P171,P176,P177,P178,P179,P180,P182,P183,P185,P187,P188,P189,P193,P194,P196,P200,P202,P204,P207,P210,P212,P213,P216,P217) -> 0
A15: 6 | B15: JUNI | F15: 0 | G15: =SUM(Q54) -> 0 | I15: =SUM(Q50,Q52,Q56) -> 1 | J15: =SUM(Q51,Q53,Q55) -> 0 | K15: =SUM(F15:J15) -> 1 | L15: 0 | M15: 0 | N15: =sum(Q93,Q95,Q96,Q103,Q108,Q109,Q114,Q116,Q117,Q120,Q122) -> 10 | O15: =sum(Q92,Q94,Q96,Q97,Q98,Q99,Q100,Q101,Q104,Q105,Q106,Q107,Q110,Q112,Q113,Q115,Q118,Q119,Q121,Q123,Q124,Q125,Q126,Q127,Q128) -> 17 | P15: =sum(Q220) -> 0 | Q15: 0 | R15: =SUM(Q149,Q150,Q152,Q153,Q154,Q155,Q156,Q159,Q160,Q162,Q164,Q166,Q167,Q172,Q173,Q174,Q175,Q181,Q184,Q186,Q190,Q191,Q192,Q195,Q197,Q198,Q199,Q201,Q203,Q205,Q206,Q208,Q209,Q211,Q214,Q215,Q218,Q219) -> 0 | S15: =SUM(Q148,Q151,Q157,Q158,Q161,Q163,Q165,Q168,Q169,Q170,Q171,Q176,Q177,Q178,Q179,Q180,Q182,Q183,Q185,Q187,Q188,Q189,Q193,Q194,Q196,Q200,Q202,Q204,Q207,Q210,Q212,Q213,Q216,Q217) -> 0
A16: 7 | B16: JULI | F16: 0 | G16: =SUM(R55) -> 0 | I16: =SUM(R50,R52,R56) -> 1 | J16: =SUM(R51,R53,R54) -> 1 | K16: =SUM(F16:J16) -> 2 | L16: 0 | M16: =sum(R126) -> 1 | N16: =sum(R93,R95,R96,R103,R108,R109,R114,R116,R117,R120,R122) -> 10 | O16: =sum(R92,R94,R96,R97,R98,R99,R100,R101,R104,R105,R106,R107,R110,R112,R113,R115,R118,R119,R121,R123,R124,R125,R126,R127,R128) -> 18 | P16: 0 | Q16: 0 | R16: =SUM(R149,R150,R152,R153,R154,R155,R156,R159,R160,R162,R164,R166,R167,R172,R173,R174,R175,R181,R184,R186,R190,R191,R192,R195,R197,R198,R199,R201,R203,R205,R206,R208,R209,R211,R214,R215,R218,R219,R220) -> 0 | S16: =SUM(R148,R151,R157,R158,R161,R163,R165,R168,R169,R170,R171,R176,R177,R178,R179,R180,R182,R183,R185,R187,R188,R189,R193,R194,R196,R200,R202,R204,R207,R210,R212,R213,R216,R217) -> 0
A17: 8 | B17: AGUSTUS | F17: 0 | G17: 0 | I17: =SUM(S50,S52,S56) -> 1 | J17: =SUM(S51,S53,S54,S55) -> 1 | K17: =SUM(F17:J17) -> 2 | L17: 0 | M17: 0 | N17: =SUM(S93,S95,S96,S103,S108,S109,S114,S116,S117,S120,S122) -> 9 | O17: =suM(S92,S94,S96,S97,S98,S99,S100,S101,S104,S105,S106,S107,S110,S112,S113,S115,S118,S119,S121,S123,S124,S125,S126,S127,S128) -> 15 | P17: 0 | Q17: 0 | R17: =SUM(S149,S150,S152,S153,S154,S155,S156,S159,S160,S162,S164,S166,S167,S172,S173,S174,S175,S181,S184,S186,S190,S191,S192,S195,S197,S198,S199,S201,S203,S205,S206,S208,S209,S211,S214,S215,S218,S219,S220) -> 0 | S17: =SUM(S148,S151,S157,S158,S161,S163,S165,S168,S169,S170,S171,S176,S177,S178,S179,S180,S182,S183,S185,S187,S188,S189,S193,S194,S196,S200,S202,S204,S207,S210,S212,S213,S216,S217) -> 0
A18: 9 | B18: SEPTEMBER | F18: =SUM(T56) -> 0 | G18: 0 | I18: =SUM(T50,T52) -> 2 | J18: =SUM(T51,T53,T54,T55) -> 1 | K18: =SUM(F18:J18) -> 3 | L18: 0 | M18: =sum(T127) -> 1 | N18: =suM(T93,T95,T96,T103,T108,T109,T114,T116,T117,T120,T122) -> 10 | O18: =suM(T92,T94,T96,T97,T98,T99,T100,T101,T104,T105,T106,T107,T110,T112,T113,T115,T118,T119,T121,T123,T124,T125,T126,T127,T128) -> 17 | P18: 0 | Q18: 0 | R18: =SUM(T149,T150,T152,T153,T154,T155,T156,T159,T160,T162,T164,T166,T167,T172,T173,T174,T175,T181,T184,T186,T190,T191,T192,T195,T197,T198,T199,T201,T203,T205,T206,T208,T209,T211,T214,T215,T218,T219,T220) -> 0 | S18: =SUM(T148,T151,T157,T158,T161,T163,T165,T168,T169,T170,T171,T176,T177,T178,T179,T180,T182,T183,T185,T187,T188,T189,T193,T194,T196,T200,T202,T204,T207,T210,T212,T213,T216,T217) -> 0
A19: 10 | B19: OKTOBER | F19: 0 | G19: 0 | I19: =SUM(U50,U52,U56) -> 2 | J19: =SUM(U51,U53,U54,U55) -> 1 | K19: =SUM(F19:J19) -> 3 | L19: 0 | M19: 0 | N19: =suM(U93,U95,U96,U103,U108,U109,U114,U116,U117,U120,U122) -> 10 | O19: =suM(U92,U94,U96,U97,U98,U99,U100,U101,U104,U105,U106,U107,U110,U112,U113,U115,U118,U119,U121,U123,U124,U125,U126,U127,U128) -> 15 | P19: 0 | Q19: =SUM(U221) -> 0 | R19: =SUM(U149,U150,U152,U153,U154,U155,U156,U159,U160,U162,U164,U166,U167,U172,U173,U174,U175,U181,U184,U186,U190,U191,U192,U195,U197,U198,U199,U201,U203,U205,U206,U208,U209,U211,U214,U215,U218,U219,U220) -> 0 | S19: =SUM(U148,U151,U157,U158,U161,U163,U165,U168,U169,U170,U171,U176,U177,U178,U179,U180,U182,U183,U185,U187,U188,U189,U193,U194,U196,U200,U202,U204,U207,U210,U212,U213,U216,U217) -> 0
A20: 11 | B20: NOVEMBER | F20: 0 | G20: 0 | I20: =SUM(V50,V52,V56) -> 2 | J20: =SUM(V51,V53,V54,V55) -> 1 | K20: =SUM(F20:J20) -> 3 | L20: 0 | M20: =sum(V128) -> 1 | N20: =suM(V93,V95,V96,V103,V108,V109,V114,V116,V117,V120,V122) -> 9 | O20: =suM(V92,V94,V96,V97,V98,V99,V100,V101,V104,V105,V106,V107,V110,V112,V113,V115,V118,V119,V121,V123,V124,V125,V126,V127,V128) -> 17 | P20: 0 | Q20: =SUM(V222) -> 0 | R20: =SUM(V149,V150,V152,V153,V154,V155,V156,V159,V160,V162,V164,V166,V167,V172,V173,V174,V175,V181,V184,V186,V190,V191,V192,V195,V197,V198,V199,V201,V203,V205,V206,V208,V209,V211,V214,V215,V218,V219,V220) -> 0 | S20: =SUM(V148,V151,V157,V158,V161,V163,V165,V168,V169,V170,V171,V176,V177,V178,V179,V180,V182,V183,V185,V187,V188,V189,V193,V194,V196,V200,V202,V204,V207,V210,V212,V213,V216,V217,V221) -> 0
A21: 12 | B21: DESEMBER | F21: 0 | G21: 0 | I21: =SUM(W50,W52,W56) -> 2 | J21: =SUM(W51,W53,W54,W55) -> 1 | K21: =SUM(F21:J21) -> 3 | L21: 0 | M21: 0 | N21: =suM(W93,W95,W96,W103,W108,W109,W114,W116,W117,W120,W122) -> 9 | O21: =suM(W92,W94,W96,W97,W98,W99,W100,W101,W104,W105,W106,W107,W110,W112,W113,W115,W118,W119,W121,W123,W124,W125,W126,W127,W128) -> 14 | P21: 0 | Q21: =SUM(W223) -> 0 | R21: =SUM(W149,W150,W152,W153,W154,W155,W156,W159,W160,W162,W164,W166,W167,W172,W173,W174,W175,W181,W184,W186,W190,W191,W192,W195,W197,W198,W199,W201,W203,W205,W206,W208,W209,W211,W214,W215,W218,W219,W220) -> 0 | S21: =SUM(W148,W151,W157,W158,W161,W163,W165,W168,W169,W170,W171,W176,W177,W178,W179,W180,W182,W183,W185,W187,W188,W189,W193,W194,W196,W200,W202,W204,W207,W210,W212,W213,W216,W217,W221,W222) -> 0
B22: TOTAL | F22: =SUM(F10:F21) -> 0 | G22: =SUM(G10:G21) -> 0 | I22: =SUM(I10:I21) -> 12 | J22: =SUM(J10:J21) -> 6 | K22: =SUM(K10:K21) -> 18 | L22: =SUM(L10:L21) -> 0 | M22: =SUM(M10:M21) -> 4 | N22: =SUM(N10:N21) -> 107 | O22: =SUM(O10:O21) -> 190 | P22: =SUM(P10:P21) -> 0 | ... S22: =SUM(S10:S21) -> 0
A24: DATA SASARAN KUNJUNGAN
A25: DESA : | B25: BUMI MAS
A26: TAHUN : | B26: 2025
A28: DATA SASARAN IBU HAMIL/NIFAS/MENYUSUI
A29: NO | B29: SASARAN IBU HAMIL/MENYUSUI | I29: USIA | J29: JUMLAH KUNJUNGAN DAN JUMLAH SASARAN IBU HAMIL/NIFAS/MENYUSUI
B30: NAMA IBU | F30: NAMA SUAMI | G30: NAMA BAYI | J30: JAN | K30: FEB | L30: MAR | M30: APR | N30: MEI | O30: JUN | P30: JUL | Q30: AGU | R30: SEP | S30: OKT | T30: NOV | U30: DES | V30: JUMLAH
A31: 1 | B31: 2 | F31: 3 | G31: 4 | J31: 5 | K31: 6 | L31: 7 | M31: 8 | N31: 9 | O31: 10 | P31: 11 | Q31: 12 | R31: 13 | S31: 14 | T31: 15 | U31: 16
A32: 1 | B32: Yayuk indiawati | F32: Supriono | G32: Kenzie alvaro devanka | J32: 1 | K32: 1 | L32: 1 | M32: 1 | N32: 1 | V32: =SUM(J32:U32) -> 5
A33: =A32+1 -> 2 | B33: Utari | F33: Doni kurniawan | G33: Handewon kurnia d | V33: =SUM(J33:U33) -> 0
A34: =A33+1 -> 3 | B34: Dinda yulia krisma | F34: Afrizal fakhri | G34: M elzavier khairan | V34: =SUM(J34:U34) -> 0
A35: =A34+1 -> 4 | B35: Putri septiana dewi | F35: Akhyar sochib | V35: =SUM(J35:U35) -> 0
A36: =A35+1 -> 5 | V36: =SUM(J36:U36) -> 0
A37: =A36+1 -> 6 | V37: =SUM(J37:U37) -> 0
A38: =A37+1 -> 7 | V38: =SUM(J38:U38) -> 0
A39: =A38+1 -> 8 | I39: =DATEDIF(G39,TODAY(),"y") -> 126 | V39: =SUM(J39:U39) -> 0
A40: JUMLAH | J40: =SUM(J32:J39) -> 1 | K40: =SUM(K32:K39) -> 1 | L40: =SUM(L32:L39) -> 1 | M40: =SUM(M32:M39) -> 1 | N40: =SUM(N32:N39) -> 1 | O40: =SUM(O32:O39) -> 0 | P40: =SUM(P32:P39) -> 0 | Q40: =SUM(Q32:Q39) -> 0 | ... V40: =SUM(V32:V39) -> 5
A46: DATA SASARAN BAYI (0-12 BULAN)
A47: NO | B47: NAMA BAYI/BALITA | F47: JENIS KELAMIN | G47: TANGGAL LAHIR | I47: USIA | J47: NAMA | L47: JUMLAH KUNJUNGAN DAN JUMLAH SASARAN BALITA BAYI 0-12 BULAN
J48: IBU | K48: AYAH | L48: JAN | M48: FEB | N48: MAR | O48: APR | P48: MEI | Q48: JUN | R48: JUL | S48: AGU | T48: SEP | U48: OKT | V48: NOV | W48: DES | X48: JUMLAH
...

Sheet Sheet14

Sheet KES SIP 6 DAHLIA
A1: DATA PENGUNJUNG
B3: DESA : BUMI MAS
A4: NO | B4: BULAN | C4: JUMLAH PENGUNJUNG | AB4: JUMLAH PETUGAS YG HADIR | AH4: JUMLAH BAYI | AL4: KET
C5: B A L I T A | L5: ANAK USIA 6-15 TAHUN | P5: USIA PRODUKTIF | T5: LANSIA | X5: WUS | Y5: IBU | AB5: KADER | AD5: PLKB | AF5: MEDIS DAN PARA MEDIS | AH5: YANG LAHIR | AJ5: MENINGGAL
C6: BAYI 0 - 12 BULAN | H6: BALITA 1-5 TAHUN | Y6: PUS | Z6: HAMIL | AA6: MENYUSUI
C7: BARU | E7: LAMA | G7: TOTAL | H7: BARU | J7: LAMA | L7: BARU | N7: LAMA | P7: BARU | R7: LAMA | T7: BARU | V7: LAMA
C8: L | D8: P | E8: L | F8: P | H8: L | I8: P | J8: L | K8: P | L8: L | M8: P | N8: L | O8: P | P8: L | Q8: P | R8: L | S8: P | T8: L | U8: P | V8: L | W8: P | AB8: L | AC8: P | AD8: L | AE8: P | AF8: L | AG8: P | AH8: L | AI8: P | AJ8: L | AK8: P
A9: 1 | B9: 2 | C9: 3 | D9: 4 | E9: 5 | F9: 6 | H9: 7 | I9: 8 | J9: 9 | K9: 10 | L9: 11 | M9: 12 | N9: 13 | O9: 14 | P9: 15 | Q9: 16 | R9: 17 | S9: 18 | T9: 19 | U9: 20 | V9: 21 | W9: 22 | X9: 23 | Y9: 24 | Z9: 25 | AA9: 26 | AB9: 27 | AC9: 28 | AD9: 29 | AE9: 30 | AF9: 31 | AG9: 32 | AH9: 33 | AI9: 34 | AJ9: 35 | AK9: 36 | AL9: 37
A10: 1 | B10: JANUARI | C10: 0 | D10: 0 | E10: =SUM(H71,H73,H77) -> 0 | F10: =SUM(H72,H74,H75,H76) -> 0 | G10: =SUM(C10:F10) -> 0 | H10: 0 | I10: =sum(H137) -> 0 | J10: =sum(H90,H92,H93,H99,H118,H119,H128,H130,H131,H134,H136) -> 4 | K10: =sum(H89,H91,H93,H94,H95,H96,H97,H98,H100,H101,H113,H114,H120,H121,H127,H129,H132,H133,H135,H137,H138,H139,H140,H141,H142) -> 10 | L10: =Sum(H218) -> 0 | M10: =sum(H219) -> 0 | N10: =SUM(H150,H151,H153,H154,H155,H156,H158,H162,H163,H165,H167,H169,H170,H175,H176,H177,H178,H184,H187,H189,H193,H194,H195,H198,H200,H201,H202,H204,H206,H208,H209,H211,H212,H214,H217) -> 0 | O10: =SUM(H149,H152,H160,H161,H164,H166,H168,H171,H172,H173,H174,H179,H180,H181,H182,H183,H185,H186,H188,H190,H191,H192,H196,H197,H199,H203,H205,H207,H210,H213,H215,H216) -> 0
A11: 2 | B11: FEBRUARI | C11: 0 | D11: 0 | E11: =SUM(I71,I73,I77) -> 0 | F11: =SUM(I72,I74,I75,I76) -> 0 | G11: =SUM(C11:F11) -> 0 | H11: 0 | I11: 0 | J11: =sum(I90,I92,I93,I99,I118,I119,I128,I130,I131,I134,I136) -> 4 | K11: =sum(I89,I91,I93,I94,I95,I96,I97,I98,I100,I101,I113,I114,I120,I121,I127,I129,I132,I133,I135,I137,I138,I139,I140,I141,I142) -> 10 | L11: 0 | M11: 0 | N11: =SUM(I150,I151,I153,I154,I155,I156,I158,I162,I163,I165,I167,I169,I170,I175,I176,I177,I178,I184,I187,I189,I193,I194,I195,I198,I200,I201,I202,I204,I206,I208,I209,I211,I212,I214,I217,I218) -> 0 | O11: =SUM(I149,I152,I160,I161,I164,I166,I168,I171,I172,I173,I174,I179,I180,I181,I182,I183,I185,I186,I188,I190,I191,I192,I196,I197,I199,I203,I205,I207,I210,I213,I215,I216,I219) -> 0
A12: 3 | B12: MARET | C12: =SUM(J71) -> 0 | D12: 0 | E12: =SUM(J73,J77) -> 0 | F12: =SUM(J72,J74,J75,J76) -> 0 | G12: =SUM(C12:F12) -> 0 | H12: 0 | I12: 0 | J12: =sum(J90,J92,J93,J99,J118,J119,J128,J130,J131,J134,J136) -> 4 | K12: =sum(J89,J91,J93,J94,J95,J96,J97,J98,J100,J101,J113,J114,J120,J121,J127,J129,J132,J133,J135,J137,J138,J139,J140,J141,J142) -> 10 | L12: 0 | M12: 0 | N12: =SUM(J150,J151,J153,J154,J155,J156,J158,J162,J163,J165,J167,J169,J170,J175,J176,J177,J178,J184,J187,J189,J193,J194,J195,J198,J200,J201,J202,J204,J206,J208,J209,J211,J212,J214,J217,J218) -> 0 | O12: =SUM(J149,J152,J160,J161,J164,J166,J168,J171,J172,J173,J174,J179,J180,J181,J182,J183,J185,J186,J188,J190,J191,J192,J196,J197,J199,J203,J205,J207,J210,J213,J215,J216,J219) -> 0
A13: 4 | B13: APRIL | C13: 1 | D13: =SUM(K72,K74) -> 0 | E13: =SUM(K71) -> 0 | F13: =SUM(K75,K76) -> 0 | G13: =SUM(C13:F13) -> 1 | H13: 0 | I13: 0 | J13: =sum(K90,K92,K93,K99,K118,K119,K128,K130,K131,K134,K136) -> 4 | K13: =sum(K89,K91,K93,K94,K95,K96,K97,K98,K100,K101,K113,K114,K120,K121,K127,K129,K132,K133,K135,K137,K138,K139,K140,K141,K142) -> 10 | L13: 0 | M13: =sum(K220) -> 0 | N13: =SUM(K150,K151,K153,K154,K155,K156,K158,K162,K163,K165,K167,K169,K170,K175,K176,K177,K178,K184,K187,K189,K193,K194,K195,K198,K200,K201,K202,K204,K206,K208,K209,K211,K212,K214,K217,K218) -> 0 | O13: =SUM(K149,K152,K160,K161,K164,K166,K168,K171,K172,K173,K174,K179,K180,K181,K182,K183,K185,K186,K188,K190,K191,K192,K196,K197,K199,K203,K205,K207,K210,K213,K215,K216,K219) -> 0
A14: 5 | B14: MEI | C14: 0 | D14: 0 | E14: 1 | F14: 0 | G14: =SUM(C14:F14) -> 1 | H14: 0 | I14: =sum(L138,L139) -> 0 | J14: =sum(L90,L92,L93,L99,L118,L119,L128,L130,L131,L134,L136) -> 4 | K14: =sum(L89,L91,L93,L94,L95,L96,L97,L98,L100,L101,L113,L114,L120,L121,L127,L129,L132,L133,L135,L137,L138,L139,L140,L141,L142) -> 10 | L14: =Sum(L221,L222) -> 0 | M14: 0 | N14: =SUM(L150,L151,L153,L154,L155,L156,L158,L162,L163,L165,L167,L169,L170,L175,L176,L177,L178,L184,L187,L189,L193,L194,L195,L198,L200,L201,L202,L204,L206,L208,L209,L211,L212,L214,L217,L218) -> 0 | O14: =SUM(L149,L152,L160,L161,L164,L166,L168,L171,L172,L173,L174,L179,L180,L181,L182,L183,L185,L186,L188,L190,L191,L192,L196,L197,L199,L203,L205,L207,L210,L213,L215,L216,L219,L220) -> 0
A15: 6 | B15: JUNI | C15: 0 | D15: =SUM(M75) -> 0 | E15: 1 | F15: 0 | G15: =SUM(C15:F15) -> 1 | H15: 0 | I15: 0 | J15: =sum(M90,M92,M93,M99,M118,M119,M128,M130,M131,M134,M136) -> 4 | K15: =sum(M89,M91,M93,M94,M95,M96,M97,M98,M100,M101,M113,M114,M120,M121,M127,M129,M132,M133,M135,M137,M138,M139,M140,M141,M142) -> 10 | L15: =sum(M223) -> 0 | M15: 0 | N15: =SUM(M150,M151,M153,M154,M155,M156,M158,M162,M163,M165,M167,M169,M170,M175,M176,M177,M178,M184,M187,M189,M193,M194,M195,M198,M200,M201,M202,M204,M206,M208,M209,M211,M212,M214,M217,M218,M221,M222) -> 0 | O15: =SUM(M149,M152,M160,M161,M164,M166,M168,M171,M172,M173,M174,M179,M180,M181,M182,M183,M185,M186,M188,M190,M191,M192,M196,M197,M199,M203,M205,M207,M210,M213,M215,M216,M219,M220) -> 0
A16: 7 | B16: JULI | C16: 0 | D16: =SUM(N76) -> 0 | E16: 1 | F16: 0 | G16: =SUM(C16:F16) -> 1 | H16: 0 | I16: =sum(N140) -> 0 | J16: =sum(N90,N92,N93,N99,N118,N119,N128,N130,N131,N134,N136) -> 4 | K16: =sum(N89,N91,N93,N94,N95,N96,N97,N98,N100,N101,N113,N114,N120,N121,N127,N129,N132,N133,N135,N137,N138,N139,N140,N141,N142) -> 10 | L16: 0 | M16: 0 | N16: =SUM(N150,N151,N153,N154,N155,N156,N158,N162,N163,N165,N167,N169,N170,N175,N176,N177,N178,N184,N187,N189,N193,N194,N195,N198,N200,N201,N202,N204,N206,N208,N209,N211,N212,N214,N217,N218,N221,N222,N223) -> 0 | O16: =SUM(N149,N152,N160,N161,N164,N166,N168,N171,N172,N173,N174,N179,N180,N181,N182,N183,N185,N186,N188,N190,N191,N192,N196,N197,N199,N203,N205,N207,N210,N213,N215,N216,N219,N220) -> 0
A17: 8 | B17: AGUSTUS | C17: 2 | D17: 0 | E17: 1 | F17: 0 | G17: =SUM(C17:F17) -> 3 | H17: 0 | I17: 0 | J17: =SUM(O90,O92,O93,O99,O118,O119,O128,O130,O131,O134,O136) -> 4 | K17: =suM(O89,O91,O93,O94,O95,O96,O97,O98,O100,O101,O113,O114,O120,O121,O127,O129,O132,O133,O135,O137,O138,O139,O140,O141,O142) -> 10 | L17: 0 | M17: 0 | N17: =SUM(O150,O151,O153,O154,O155,O156,O158,O162,O163,O165,O167,O169,O170,O175,O176,O177,O178,O184,O187,O189,O193,O194,O195,O198,O200,O201,O202,O204,O206,O208,O209,O211,O212,O214,O217,O218,O221,O222,O223) -> 0 | O17: =SUM(O149,O152,O160,O161,O164,O166,O168,O171,O172,O173,O174,O179,O180,O181,O182,O183,O185,O186,O188,O190,O191,O192,O196,O197,O199,O203,O205,O207,O210,O213,O215,O216,O219,O220) -> 0
A18: 9 | B18: SEPTEMBER | C18: =SUM(P77) -> 0 | D18: 1 | E18: 3 | F18: 0 | G18: =SUM(C18:F18) -> 4 | H18: 0 | I18: =sum(P141) -> 0 | J18: =suM(P90,P92,P93,P99,P118,P119,P128,P130,P131,P134,P136) -> 4 | K18: =suM(P89,P91,P93,P94,P95,P96,P97,P98,P100,P101,P113,P114,P120,P121,P127,P129,P132,P133,P135,P137,P138,P139,P140,P141,P142) -> 10 | L18: 0 | M18: 0 | N18: =SUM(P150,P151,P153,P154,P155,P156,P158,P162,P163,P165,P167,P169,P170,P175,P176,P177,P178,P184,P187,P189,P193,P194,P195,P198,P200,P201,P202,P204,P206,P208,P209,P211,P212,P214,P217,P218,P221,P222,P223) -> 0 | O18: =SUM(P149,P152,P160,P161,P164,P166,P168,P171,P172,P173,P174,P179,P180,P181,P182,P183,P185,P186,P188,P190,P191,P192,P196,P197,P199,P203,P205,P207,P210,P213,P215,P216,P219,P220) -> 0
A19: 10 | B19: OKTOBER | C19: 0 | D19: 0 | E19: 3 | F19: 1 | G19: =SUM(C19:F19) -> 4 | H19: 0 | I19: 0 | J19: =suM(Q90,Q92,Q93,Q99,Q118,Q119,Q128,Q130,Q131,Q134,Q136) -> 4 | K19: =suM(Q89,Q91,Q93,Q94,Q95,Q96,Q97,Q98,Q100,Q101,Q113,Q114,Q120,Q121,Q127,Q129,Q132,Q133,Q135,Q137,Q138,Q139,Q140,Q141,Q142) -> 10 | L19: 0 | M19: =SUM(Q224) -> 0 | N19: =SUM(Q150,Q151,Q153,Q154,Q155,Q156,Q158,Q162,Q163,Q165,Q167,Q169,Q170,Q175,Q176,Q177,Q178,Q184,Q187,Q189,Q193,Q194,Q195,Q198,Q200,Q201,Q202,Q204,Q206,Q208,Q209,Q211,Q212,Q214,Q217,Q218,Q221,Q222,Q223) -> 0 | O19: =SUM(Q149,Q152,Q160,Q161,Q164,Q166,Q168,Q171,Q172,Q173,Q174,Q179,Q180,Q181,Q182,Q183,Q185,Q186,Q188,Q190,Q191,Q192,Q196,Q197,Q199,Q203,Q205,Q207,Q210,Q213,Q215,Q216,Q219,Q220) -> 0
A20: 11 | B20: NOVEMBER | C20: 0 | D20: 0 | E20: 3 | F20: 1 | G20: =SUM(C20:F20) -> 4 | H20: 0 | I20: =sum(R142) -> 0 | J20: =suM(R90,R92,R93,R99,R118,R119,R128,R130,R131,R134,R136) -> 4 | K20: =suM(R89,R91,R93,R94,R95,R96,R97,R98,R100,R101,R113,R114,R120,R121,R127,R129,R132,R133,R135,R137,R138,R139,R140,R141,R142) -> 10 | L20: 0 | M20: =SUM(R225) -> 0 | N20: =SUM(R150,R151,R153,R154,R155,R156,R158,R162,R163,R165,R167,R169,R170,R175,R176,R177,R178,R184,R187,R189,R193,R194,R195,R198,R200,R201,R202,R204,R206,R208,R209,R211,R212,R214,R217,R218,R221,R222,R223) -> 0 | O20: =SUM(R149,R152,R160,R161,R164,R166,R168,R171,R172,R173,R174,R179,R180,R181,R182,R183,R185,R186,R188,R190,R191,R192,R196,R197,R199,R203,R205,R207,R210,R213,R215,R216,R219,R220,R224) -> 0
A21: 12 | B21: DESEMBER | C21: 2 | D21: 0 | E21: 0 | F21: 1 | G21: =SUM(C21:F21) -> 3 | H21: 0 | I21: 0 | J21: =suM(S90,S92,S93,S99,S118,S119,S128,S130,S131,S134,S136) -> 4 | K21: =suM(S89,S91,S93,S94,S95,S96,S97,S98,S100,S101,S113,S114,S120,S121,S127,S129,S132,S133,S135,S137,S138,S139,S140,S141,S142) -> 10 | L21: 0 | M21: =SUM(S226) -> 0 | N21: =SUM(S150,S151,S153,S154,S155,S156,S158,S162,S163,S165,S167,S169,S170,S175,S176,S177,S178,S184,S187,S189,S193,S194,S195,S198,S200,S201,S202,S204,S206,S208,S209,S211,S212,S214,S217,S218,S221,S222,S223) -> 0 | O21: =SUM(S149,S152,S160,S161,S164,S166,S168,S171,S172,S173,S174,S179,S180,S181,S182,S183,S185,S186,S188,S190,S191,S192,S196,S197,S199,S203,S205,S207,S210,S213,S215,S216,S219,S220,S224,S225) -> 0
B22: TOTAL | C22: =SUM(C10:C21) -> 5 | D22: =SUM(D10:D21) -> 1 | E22: =SUM(E10:E21) -> 13 | F22: =SUM(F10:F21) -> 3 | G22: =SUM(G10:G21) -> 22 | H22: =SUM(H10:H21) -> 0 | I22: =SUM(I10:I21) -> 0 | J22: =SUM(J10:J21) -> 48 | ... O22: =SUM(O10:O21) -> 0
A24: DATA SASARAN KUNJUNGAN
A25: DESA : | B25: BUMI MAS
A26: TAHUN : | B26: 2025
A28: DATA SASARAN IBU HAMIL/NIFAS/MENYUSUI
A29: NO | B29: SASARAN IBU HAMIL/MENYUSUI | E29: Tanggal Lahir | F29: JUMLAH KUNJUNGAN DAN JUMLAH SASARAN IBU HAMIL/NIFAS/MENYUSUI
B30: NAMA IBU | C30: NAMA SUAMI | D30: NAMA BAYI | F30: JAN | G30: FEB | H30: MAR | I30: APR | J30: MEI | K30: JUN | L30: JUL | M30: AGU | N30: SEP | O30: OKT | P30: NOV | Q30: DES | R30: JUMLAH
A31: 1 | B31: 2 | C31: 3 | D31: 4 | F31: 5 | G31: 6 | H31: 7 | I31: 8 | J31: 9 | K31: 10 | L31: 11 | M31: 12 | N31: 13 | O31: 14 | P31: 15 | Q31: 16
A32: 1 | B32: Rilliana Suci Lestari | C32: Arif Wicaksono | D32: - | F32: 0 | G32: 0 | H32: 0 | I32: 0 | J32: 1 | K32: 0 | L32: 0 | M32: 1 | N32: 0 | O32: 1 | P32: 1 | Q32: 0 | R32: 4
A33: 2 | B33: Niken Andriani | C33: Frenky jakaria | D33: Muhammad Azam Ghazy | E33: 46007 | F33: 0 | G33: 0 | H33: 0 | I33: 0 | J33: 0 | K33: 0 | L33: 0 | M33: 0 | N33: 0 | O33: 0 | P33: 0 | Q33: 0 | R33: =SUM(F33:Q33) -> 0
A34: 3 | B34: Laelatul Qodariah | C34: Wahyu Prasetyo | D34: Bilal Arshaka Prastyo | E34: 45995 | F34: 0 | G34: 0 | H34: 0 | I34: 0 | J34: 0 | K34: 0 | L34: 0 | M34: 0 | N34: 0 | O34: 0 | P34: 0 | Q34: 0 | R34: =SUM(F34:Q34) -> 0
A35: 4 | B35: Selvi Yundasari | C35: Budi Susilo | D35: Rezqiana Shakiera Zahbia | E35: 45456 | F35: 1 | G35: 1 | H35: 1 | I35: 1 | J35: 1 | K35: 1 | L35: 1 | M35: 0 | N35: 1 | O35: 1 | P35: 1 | Q35: 1 | R35: 11
A36: 5 | B36: Ernella Muhsanti | C36: Yuda Prasetya | D36: Genanzio Mehan Prasetya | E36: 45411 | F36: 1 | G36: 1 | H36: 1 | I36: 1 | J36: 1 | K36: 1 | L36: 1 | M36: 1 | N36: 1 | O36: 1 | P36: 1 | Q36: 1 | R36: 12
A37: 6 | B37: Fenti Farida | C37: DWi Ardian Prabowo | D37: Naura Zefanya Ramlan | E37: 45626 | F37: 1 | G37: 1 | H37: 1 | I37: 1 | J37: 1 | K37: 1 | L37: 1 | M37: 1 | N37: 1 | O37: 1 | P37: 1 | Q37: 1 | R37: 12
A38: 7 | B38: Fenti Farida | C38: DWi Ardian Prabowo | D38: Naira Kayla Ramlan | E38: 45626 | F38: 1 | G38: 1 | H38: 1 | I38: 1 | J38: 1 | K38: 1 | L38: 1 | M38: 1 | N38: 1 | O38: 1 | P38: 1 | Q38: 1 | R38: 12
A39: 8 | B39: Rima Nevita | C39: Bayu Hermawan | D39: - | F39: 0 | G39: 0 | H39: 0 | I39: 0 | J39: 0 | K39: 1 | L39: 1 | M39: 0 | N39: 1 | O39: 0 | P39: 0 | Q39: 0 | R39: =SUM(F39:Q39) -> 3
A40: 9 | B40: Yeni Irawati | C40: Muhammad Fahrurozy | D40: - | F40: 0 | G40: 0 | H40: 0 | I40: 1 | J40: 1 | K40: 1 | L40: 0 | M40: 0 | N40: 1 | O40: 0 | P40: 0 | Q40: 0 | R40: =SUM(F40:Q40) -> 4
A41: 10 | B41: Deni Astutik | C41: Yudi Yanto | D41: Elbarra Rygananta | E41: 45898 | F41: 0 | G41: 0 | H41: 0 | I41: 0 | J41: 0 | K41: 0 | L41: 0 | M41: 0 | N41: 1 | O41: 1 | P41: 1 | Q41: 1 | R41: =SUM(F41:Q41) -> 4
A42: 11 | B42: Siti Rohmah | C42: Musana Ardika | D42: Nada Almahira Qirani | F42: 1 | G42: 1 | H42: 1 | I42: 1 | J42: 1 | K42: 1 | L42: 1 | M42: 1 | N42: 1 | O42: 1 | P42: 1 | Q42: 1 | R42: =SUM(F42:Q42) -> 12
A43: 12 | B43: Siti Nur Salamah | C43: Qoirul Anam | D43: Amera Zoya Annaila | F43: 1 | G43: 1 | H43: 1 | I43: 1 | J43: 1 | K43: 1 | L43: 1 | M43: 1 | N43: 1 | O43: 1 | P43: 1 | Q43: 1 | R43: =SUM(F43:Q43) -> 12
...

Sheet KES SIP 6 MELATI
A1: DATA PENGUNJUNG
A3: DESA | B3: : BUMI MAS
A4: NO | B4: BULAN | C4: JUMLAH PENGUNJUNG | AB4: JUMLAH PETUGAS YG HADIR | AH4: JUMLAH BAYI | AL4: KET
C5: B A L I T A | L5: ANAK USIA 6-15 TAHUN | P5: USIA PRODUKTIF | T5: LANSIA | X5: WUS | Y5: IBU | AB5: KADER | AD5: PLKB | AF5: MEDIS DAN PARA MEDIS | AH5: YANG LAHIR | AJ5: MENINGGAL
C6: BAYI 0 - 12 BULAN | H6: BALITA 1-5 TAHUN | Y6: PUS | Z6: HAMIL | AA6: MENYUSUI
C7: BARU | E7: LAMA | G7: TOTAL | H7: BARU | J7: LAMA | L7: BARU | N7: LAMA | P7: BARU | R7: LAMA | T7: BARU | V7: LAMA
C8: L | D8: P | E8: L | F8: P | H8: L | I8: P | J8: L | K8: P | L8: L | M8: P | N8: L | O8: P | P8: L | Q8: P | R8: L | S8: P | T8: L | U8: P | V8: L | W8: P | AB8: L | AC8: P | AD8: L | AE8: P | AF8: L | AG8: P | AH8: L | AI8: P | AJ8: L | AK8: P
A9: 1 | B9: 2 | C9: 3 | D9: 4 | E9: 5 | F9: 6 | H9: 7 | I9: 8 | J9: 9 | K9: 10 | L9: 11 | M9: 12 | N9: 13 | O9: 14 | P9: 15 | Q9: 16 | R9: 17 | S9: 18 | T9: 19 | U9: 20 | V9: 21 | W9: 22 | X9: 23 | Y9: 24 | Z9: 25 | AA9: 26 | AB9: 27 | AC9: 28 | AD9: 29 | AE9: 30 | AF9: 31 | AG9: 32 | AH9: 33 | AI9: 34 | AJ9: 35 | AK9: 36 | AL9: 37
A10: 1 | B10: JANUARI | C10: 0 | D10: 0 | E10: =SUM(H69,H71,H75) -> 0 | F10: =SUM(H66:H68) -> 3 | G10: =SUM(C10:F10) -> 3 | H10: 0 | I10: =sum(H91) -> 1 | J10: =sum(H108,H110,H111,H117,H122,H123,H82,H84,H85,H88,H90) -> 8 | K10: =sum(H107,H109,H111,H112,H113,H114,H115,H116,H118,H119,H120,H121,H124,H125,H126,H83,H86,H87,H89,H91,H92,H93,H66,H67,H68) -> 14 | L10: =Sum(H201) -> 1 | M10: =sum(H202) -> 1 | N10: =SUM(H135,H136,H138,H139,H140,H141,H142,H145,H146,H148,H150,H152,H153,H158,H159,H160,H161,H167,H170,H172,H176,H177,H178,H181,H183,H184,H185,H187,H189,H191,H192,H194,H195,H197,H200) -> 2 | O10: =SUM(H134,H137,H143,H144,H147,H149,H151,H154,H155,H156,H157,H162,H163,H164,H165,H166,H168,H169,H171,H173,H174,H175,H179,H180,H182,H186,H188,H190,H193,H196,H198,H199) -> 2 | T10: 0 | U10: 0 | V10: 22 | W10: 7 | X10: 173 | Y10: 121 | Z10: =A55 -> 23
A11: 2 | B11: FEBRUARI | C11: 0 | D11: 0 | E11: =SUM(I69,I71,I75) -> 0 | F11: =sum(I66:I68) -> 3 | G11: =SUM(C11:F11) -> 3 | H11: 0 | I11: 0 | J11: =sum(I108,I110,I111,I117,I122,I123,I82,I84,I85,I88,I90) -> 6 | K11: =sum(I107,I109,I111,I112,I113,I114,I115,I116,I118,I119,I120,I121,I124,I125,I126,I83,I86,I87,I89,I91,I92,I93,I66,I67,I68) -> 16 | L11: 0 | M11: 0 | N11: =SUM(I135,I136,I138,I139,I140,I141,I142,I145,I146,I148,I150,I152,I153,I158,I159,I160,I161,I167,I170,I172,I176,I177,I178,I181,I183,I184,I185,I187,I189,I191,I192,I194,I195,I197,I200,I201) -> 2 | O11: =SUM(I134,I137,I143,I144,I147,I149,I151,I154,I155,I156,I157,I162,I163,I164,I165,I166,I168,I169,I171,I173,I174,I175,I179,I180,I182,I186,I188,I190,I193,I196,I198,I199,I202) -> 3 | T11: 0 | U11: 0 | V11: 22 | W11: 7 | X11: 173 | Y11: 121
A12: 3 | B12: MARET | C12: =SUM(J69) -> 1 | D12: 0 | E12: =SUM(J71,J75) -> 0 | F12: =sum(I66:I68) -> 3 | G12: =SUM(C12:F12) -> 4 | H12: 0 | I12: 0 | J12: =sum(J108,J110,J111,J117,J122,J123,J82,J84,J85,J88,J90) -> 4 | K12: =sum(J107,J109,J111,J112,J113,J114,J115,J116,J118,J119,J120,J121,J124,J125,J126,J83,J86,J87,J89,J91,J92,J93,J66,J67,J68) -> 14 | L12: 0 | M12: 0 | N12: =SUM(J135,J136,J138,J139,J140,J141,J142,J145,J146,J148,J150,J152,J153,J158,J159,J160,J161,J167,J170,J172,J176,J177,J178,J181,J183,J184,J185,J187,J189,J191,J192,J194,J195,J197,J200,J201) -> 4 | O12: =SUM(J134,J137,J143,J144,J147,J149,J151,J154,J155,J156,J157,J162,J163,J164,J165,J166,J168,J169,J171,J173,J174,J175,J179,J180,J182,J186,J188,J190,J193,J196,J198,J199,J202) -> 3 | T12: 0 | U12: 0 | V12: 22 | W12: 7 | X12: 173 | Y12: 121
A13: 4 | B13: APRIL | C13: =SUM(K71) -> 1 | D13: =SUM(K70,K72) -> 2 | E13: =SUM(K69) -> 1 | F13: =SUM(K66:K68) -> 2 | G13: =SUM(C13:F13) -> 6 | H13: 0 | I13: 0 | J13: =sum(K108,K110,K111,K117,K122,K123,K82,K84,K85,K88,K90) -> 6 | K13: =sum(K107,K109,K111,K112,K113,K114,K115,K116,K118,K119,K120,K121,K124,K125,K126,K83,K86,K87,K89,K91,K92,K93,K66,K67,K68) -> 17 | L13: 0 | M13: =sum(K203) -> 1 | N13: =SUM(K135,K136,K138,K139,K140,K141,K142,K145,K146,K148,K150,K152,K153,K158,K159,K160,K161,K167,K170,K172,K176,K177,K178,K181,K183,K184,K185,K187,K189,K191,K192,K194,K195,K197,K200,K201) -> 3 | O13: =SUM(K134,K137,K143,K144,K147,K149,K151,K154,K155,K156,K157,K162,K163,K164,K165,K166,K168,K169,K171,K173,K174,K175,K179,K180,K182,K186,K188,K190,K193,K196,K198,K199,K202) -> 3 | T13: 0 | U13: 0 | V13: 22 | W13: 7 | X13: 173 | Y13: 121
A14: 5 | B14: MEI | C14: 0 | D14: 0 | E14: =SUM(L69,L71) -> 2 | F14: =SUM(L66:L68,L70,L72) -> 4 | G14: =SUM(C14:F14) -> 6 | H14: 0 | I14: =sum(L92,L93) -> 2 | J14: =sum(L108,L110,L111,L117,L122,L123,L82,L84,L85,L88,L90) -> 4 | K14: =sum(L107,L109,L111,L112,L113,L114,L115,L116,L118,L119,L120,L121,L124,L125,L126,L83,L86,L87,L89,L91,L92,L93,L66,L67,L68) -> 14 | L14: =Sum(L101,L102) -> 2 | M14: 0 | N14: =SUM(L135,L136,L138,L139,L140,L141,L142,L145,L146,L148,L150,L152,L153,L158,L159,L160,L161,L167,L170,L172,L176,L177,L178,L181,L183,L184,L185,L187,L189,L191,L192,L194,L195,L197,L200,L201) -> 2 | O14: =SUM(L134,L137,L143,L144,L147,L149,L151,L154,L155,L156,L157,L162,L163,L164,L165,L166,L168,L169,L171,L173,L174,L175,L179,L180,L182,L186,L188,L190,L193,L196,L198,L199,L202,L203) -> 5 | T14: 1 | U14: 0 | V14: 23 | W14: 7 | X14: 173 | Y14: 121
A15: 6 | B15: JUNI | C15: 0 | D15: =SUM(M73) -> 1 | E15: =SUM(M69,M71,M75) -> 2 | F15: =SUM(M66:M68,M70,M72) -> 3 | G15: =SUM(C15:F15) -> 6 | H15: 0 | I15: 0 | J15: =sum(M108,M110,M111,M117,M122,M123,M82,M84,M85,M88,M90) -> 4 | K15: =sum(M107,M109,M111,M112,M113,M114,M115,M116,M118,M119,M120,M121,M124,M125,M126,M83,M86,M87,M89,M91,M92,M93,M66,M67,M68) -> 15 | L15: =sum(M103) -> 1 | M15: 0 | N15: =SUM(M135,M136,M138,M139,M140,M141,M142,M145,M146,M148,M150,M152,M153,M158,M159,M160,M161,M167,M170,M172,M176,M177,M178,M181,M183,M184,M185,M187,M189,M191,M192,M194,M195,M197,M200,M201,M101,M102) -> 3 | O15: =SUM(M134,M137,M143,M144,M147,M149,M151,M154,M155,M156,M157,M162,M163,M164,M165,M166,M168,M169,M171,M173,M174,M175,M179,M180,M182,M186,M188,M190,M193,M196,M198,M199,M202,M203) -> 1 | T15: 1 | U15: 0 | V15: 24 | W15: 7 | X15: 173 | Y15: 121
A16: 7 | B16: JULI | C16: 0 | D16: =SUM(N74) -> 1 | E16: =SUM(N71) -> 1 | F16: =SUM(N66:N68,N70,N72,N73) -> 5 | G16: =SUM(C16:F16) -> 7 | H16: 0 | I16: =sum(N66) -> 1 | J16: =sum(N108,N110,N111,N117,N122,N123,N82,N84,N85,N88,N90) -> 5 | K16: =sum(N107,N109,N111,N112,N113,N114,N115,N116,N118,N119,N120,N121,N124,N125,N126,N83,N86,N87,N89,N91,N92,N93,N66,N67,N68) -> 14 | L16: 0 | M16: 0 | N16: =SUM(N135,N136,N138,N139,N140,N141,N142,N145,N146,N148,N150,N152,N153,N158,N159,N160,N161,N167,N170,N172,N176,N177,N178,N181,N183,N184,N185,N187,N189,N191,N192,N194,N195,N197,N200,N201,N101,N102,N103) -> 1 | O16: =SUM(N134,N137,N143,N144,N147,N149,N151,N154,N155,N156,N157,N162,N163,N164,N165,N166,N168,N169,N171,N173,N174,N175,N179,N180,N182,N186,N188,N190,N193,N196,N198,N199,N202,N203) -> 1 | T16: 1 | U16: 1 | V16: 25 | W16: 8 | X16: 173 | Y16: 121
A17: 8 | B17: AGUSTUS | C17: 0 | D17: 0 | E17: =SUM(O69,O71) -> 2 | F17: =SUM(O66:O68,O70,O72,O73,O74) -> 6 | G17: =SUM(C17:F17) -> 8 | H17: 0 | I17: 0 | J17: =SUM(O108,O110,O111,O117,O122,O123,O82,O84,O85,O88,O90) -> 5 | K17: =suM(O107,O109,O111,O112,O113,O114,O115,O116,O118,O119,O120,O121,O124,O125,O126,O83,O86,O87,O89,O91,O92,O93,O66,O67,O68) -> 13 | L17: 0 | M17: 0 | N17: =SUM(O135,O136,O138,O139,O140,O141,O142,O145,O146,O148,O150,O152,O153,O158,O159,O160,O161,O167,O170,O172,O176,O177,O178,O181,O183,O184,O185,O187,O189,O191,O192,O194,O195,O197,O200,O201,O101,O102,O103) -> 0 | O17: =SUM(O134,O137,O143,O144,O147,O149,O151,O154,O155,O156,O157,O162,O163,O164,O165,O166,O168,O169,O171,O173,O174,O175,O179,O180,O182,O186,O188,O190,O193,O196,O198,O199,O202,O203) -> 1 | T17: 1 | U17: 0 | V17: 26 | W17: 8 | X17: 173 | Y17: 121
A18: 9 | B18: SEPTEMBER | C18: =SUM(P75) -> 1 | D18: 0 | E18: =SUM(P69,P71) -> 2 | F18: =SUM(P66:P68,P70,P72,P73,P74) -> 6 | G18: =SUM(C18:F18) -> 9 | H18: 0 | I18: =sum(P67) -> 1 | J18: =suM(P108,P110,P111,P117,P122,P123,P82,P84,P85,P88,P90) -> 6 | K18: =suM(P107,P109,P111,P112,P113,P114,P115,P116,P118,P119,P120,P121,P124,P125,P126,P83,P86,P87,P89,P91,P92,P93,P66,P67,P68) -> 15 | L18: 0 | M18: 0 | N18: =SUM(P135,P136,P138,P139,P140,P141,P142,P145,P146,P148,P150,P152,P153,P158,P159,P160,P161,P167,P170,P172,P176,P177,P178,P181,P183,P184,P185,P187,P189,P191,P192,P194,P195,P197,P200,P201,P101,P102,P103) -> 2 | O18: =SUM(P134,P137,P143,P144,P147,P149,P151,P154,P155,P156,P157,P162,P163,P164,P165,P166,P168,P169,P171,P173,P174,P175,P179,P180,P182,P186,P188,P190,P193,P196,P198,P199,P202,P203) -> 1 | T18: 0 | U18: 0 | V18: 26 | W18: 8 | X18: 173 | Y18: 121
A19: 10 | B19: OKTOBER | C19: 0 | D19: 0 | E19: =SUM(Q69,Q71,Q75) -> 3 | F19: =SUM(Q66:Q68,Q70,Q72,Q73,Q74) -> 4 | G19: =SUM(C19:F19) -> 7 | H19: 0 | I19: 0 | J19: =suM(Q108,Q110,Q111,Q117,Q122,Q123,Q82,Q84,Q85,Q88,Q90) -> 6 | K19: =suM(Q107,Q109,Q111,Q112,Q113,Q114,Q115,Q116,Q118,Q119,Q120,Q121,Q124,Q125,Q126,Q83,Q86,Q87,Q89,Q91,Q92,Q93,Q66,Q67,Q68) -> 13 | L19: 0 | M19: =SUM(Q104) -> 1 | N19: =SUM(Q135,Q136,Q138,Q139,Q140,Q141,Q142,Q145,Q146,Q148,Q150,Q152,Q153,Q158,Q159,Q160,Q161,Q167,Q170,Q172,Q176,Q177,Q178,Q181,Q183,Q184,Q185,Q187,Q189,Q191,Q192,Q194,Q195,Q197,Q200,Q201,Q101,Q102,Q103) -> 3 | O19: =SUM(Q134,Q137,Q143,Q144,Q147,Q149,Q151,Q154,Q155,Q156,Q157,Q162,Q163,Q164,Q165,Q166,Q168,Q169,Q171,Q173,Q174,Q175,Q179,Q180,Q182,Q186,Q188,Q190,Q193,Q196,Q198,Q199,Q202,Q203) -> 0 | T19: 0 | U19: 2 | V19: 26 | W19: 10 | X19: 173 | Y19: 121
A20: 11 | B20: NOVEMBER | C20: 0 | D20: 0 | E20: =SUM(Q69,Q71,Q75) -> 3 | F20: =SUM(R66:R68,R70,R72,R73,R74) -> 7 | G20: =SUM(C20:F20) -> 10 | H20: 0 | I20: =sum(R68) -> 1 | J20: =suM(R108,R110,R111,R117,R122,R123,R82,R84,R85,R88,R90) -> 8 | K20: =suM(R107,R109,R111,R112,R113,R114,R115,R116,R118,R119,R120,R121,R124,R125,R126,R83,R86,R87,R89,R91,R92,R93,R66,R67,R68) -> 15 | L20: 0 | M20: =SUM(R105) -> 1 | N20: =SUM(R135,R136,R138,R139,R140,R141,R142,R145,R146,R148,R150,R152,R153,R158,R159,R160,R161,R167,R170,R172,R176,R177,R178,R181,R183,R184,R185,R187,R189,R191,R192,R194,R195,R197,R200,R201,R101,R102,R103) -> 2 | O20: =SUM(R134,R137,R143,R144,R147,R149,R151,R154,R155,R156,R157,R162,R163,R164,R165,R166,R168,R169,R171,R173,R174,R175,R179,R180,R182,R186,R188,R190,R193,R196,R198,R199,R202,R203,R104) -> 2 | T20: 0 | U20: 0 | V20: 26 | W20: 10 | X20: 173 | Y20: 121
A21: 12 | B21: DESEMBER | C21: 0 | D21: 0 | E21: =SUM(S69,S71,S75) -> 2 | F21: =SUM(S66:S68,S70,S72,S73,S74) -> 5 | G21: =SUM(C21:F21) -> 7 | H21: 0 | I21: 0 | J21: =suM(S108,S110,S111,S117,S122,S123,S82,S84,S85,S88,S90) -> 8 | K21: =suM(S107,S109,S111,S112,S113,S114,S115,S116,S118,S119,S120,S121,S124,S125,S126,S83,S86,S87,S89,S91,S92,S93,S66,S67,S68) -> 14 | L21: 0 | M21: =SUM(S106) -> 1 | N21: =SUM(S135,S136,S138,S139,S140,S141,S142,S145,S146,S148,S150,S152,S153,S158,S159,S160,S161,S167,S170,S172,S176,S177,S178,S181,S183,S184,S185,S187,S189,S191,S192,S194,S195,S197,S200,S201,S101,S102,S103) -> 1 | O21: =SUM(S134,S137,S143,S144,S147,S149,S151,S154,S155,S156,S157,S162,S163,S164,S165,S166,S168,S169,S171,S173,S174,S175,S179,S180,S182,S186,S188,S190,S193,S196,S198,S199,S202,S203,S104,S105) -> 3 | T21: 0 | U21: 1 | V21: 26 | W21: 11 | X21: 173 | Y21: 121
B22: TOTAL | C22: =SUM(C10:C21) -> 3 | D22: =SUM(D10:D21) -> 4 | E22: =SUM(E10:E21) -> 18 | F22: =SUM(F10:F21) -> 51 | G22: =SUM(G10:G21) -> 76 | H22: =SUM(H10:H21) -> 0 | I22: =SUM(I10:I21) -> 6 | J22: =SUM(J10:J21) -> 70 | ... AL22: =SUM(AL10:AL21) -> 0
A25: DATA SASARAN KUNJUNGAN | V25: 26 | W25: 11
A26: DESA : | B26: BUMI MAS
A27: TAHUN : | B27: 2025
A29: DATA SASARAN IBU HAMIL/NIFAS/MENYUSUI
A30: NO | B30: SASARAN IBU HAMIL/MENYUSUI | E30: Tanggal Lahir | F30: JUMLAH KUNJUNGAN DAN JUMLAH SASARAN IBU HAMIL/NIFAS/MENYUSUI
B31: NAMA IBU | C31: NAMA SUAMI | D31: NAMA BAYI | E31: Bayi | F31: JAN | G31: FEB | H31: MAR | I31: APR | J31: MEI | K31: JUN | L31: JUL | M31: AGU | N31: SEP | O31: OKT | P31: NOV | Q31: DES | R31: JUMLAH
A32: 1 | B32: 2 | C32: 3 | D32: 4 | F32: 5 | G32: 6 | H32: 7 | I32: 8 | J32: 9 | K32: 10 | L32: 11 | M32: 12 | N32: 13 | O32: 14 | P32: 15 | Q32: 16
A33: 1 | B33: Yuli Partini | C33: AHmad Abadi | D33: Umar Aasim Daefullah | E33: 44930 | F33: 1 | G33: 1 | H33: 1 | I33: 1 | J33: 0 | K33: 0 | L33: 0 | M33: 0 | N33: 0 | O33: 1 | P33: 1 | Q33: 1 | R33: =SUM(F33:Q33) -> 7
A34: =A33+1 -> 2 | B34: Eka Widyasari | C34: Suhermanto | D34: Ersha Shakiya Putri | E34: 44931 | F34: 1 | G34: 1 | H34: 1 | I34: 1 | J34: 1 | K34: 1 | L34: 1 | M34: 0 | N34: 0 | O34: 0 | P34: 1 | Q34: 1 | R34: =SUM(F34:Q34) -> 9
A35: =A34+1 -> 3 | B35: Annisaul Mahmudah | C35: Santoso | D35: Muhammad Hanan | E35: 44993 | F35: 1 | G35: 1 | H35: 0 | I35: 0 | J35: 0 | K35: 1 | L35: 1 | M35: 1 | N35: 1 | O35: 1 | P35: 1 | Q35: 1 | R35: =SUM(F35:Q35) -> 9
A36: =A35+1 -> 4 | B36: Annisaul Mahmudah | C36: Santoso | D36: Muhammad Hamim | E36: 44993 | F36: 1 | G36: 1 | H36: 0 | I36: 0 | J36: 0 | K36: 1 | L36: 1 | M36: 1 | N36: 1 | O36: 1 | P36: 1 | Q36: 1 | R36: =SUM(F36:Q36) -> 9
A37: =A36+1 -> 5 | B37: Siti Ngaliyah | C37: Edi Saputra | D37: Afida Salsabila Alifah | E37: 45034 | F37: 1 | G37: 1 | H37: 1 | I37: 1 | J37: 1 | K37: 1 | L37: 0 | M37: 1 | N37: 1 | O37: 1 | P37: 0 | Q37: 1 | R37: =SUM(F37:Q37) -> 10
A38: =A37+1 -> 6 | B38: Susiloningsih | C38: Sukamdo | D38: Rayyan Arfinza D | E38: 45047 | F38: 1 | G38: 1 | H38: 1 | I38: 1 | J38: 1 | K38: 1 | L38: 1 | M38: 1 | N38: 1 | O38: 1 | P38: 1 | Q38: 1 | R38: =SUM(F38:Q38) -> 12
A39: =A38+1 -> 7 | B39: Desi Ratnasai | C39: Edi Riyanto | D39: Afika Nur Aisyah | E39: 45062 | F39: 0 | G39: 0 | H39: 1 | I39: 1 | J39: 1 | K39: 0 | L39: 0 | M39: 0 | N39: 0 | O39: 1 | P39: 1 | Q39: 1 | R39: =SUM(F39:Q39) -> 6
A40: =A39+1 -> 8 | B40: Endang Palupi | C40: Mansuryono | D40: Nawa Syarif H | E40: 45138 | F40: 1 | G40: 1 | H40: 1 | I40: 1 | J40: 1 | K40: 1 | L40: 1 | M40: 1 | N40: 1 | O40: 1 | P40: 1 | Q40: 1 | R40: =SUM(F40:Q40) -> 12
A41: =A40+1 -> 9 | B41: Bainun | C41: Dwi Mulya Rosadi | D41: Muhammad Bagas M | E41: 45223 | F41: 1 | G41: 0 | H41: 0 | I41: 1 | J41: 1 | K41: 0 | L41: 1 | M41: 1 | N41: 1 | O41: 0 | P41: 0 | Q41: 1 | R41: =SUM(F41:Q41) -> 7
A42: =A41+1 -> 10 | B42: Tri Setianingsih | C42: Tulus Saputra | D42: Zea Shaqweena | E42: 45306 | F42: 1 | G42: 1 | H42: 0 | I42: 0 | J42: 0 | K42: 0 | L42: 0 | M42: 0 | N42: 0 | O42: 0 | P42: 0 | Q42: 0 | R42: =SUM(F42:Q42) -> 2
A43: =A42+1 -> 11 | B43: Ellysa F | C43: Dika Prayoga | D43: Devanya Queensha P | E43: 45419 | F43: 0 | G43: 0 | H43: 0 | I43: 0 | J43: 1 | K43: 0 | L43: 0 | M43: 0 | N43: 0 | O43: 1 | P43: 0 | Q43: 1 | R43: =SUM(F43:Q43) -> 3
A44: =A43+1 -> 12 | B44: Siti Marfuah | C44: Tohir | D44: Nadhira Khansa Aulia | E44: 45428 | F44: 0 | G44: 1 | H44: 1 | I44: 1 | J44: 1 | K44: 1 | L44: 1 | M44: 1 | N44: 1 | O44: 1 | P44: 1 | Q44: 1 | R44: =SUM(F44:Q44) -> 11
...

Sheet KES SIP 6 BUMIMAS
A1: DATA PENGUNJUNG
B3: DESA : BUMI MAS
A4: NO | B4: BULAN | C4: JUMLAH PENGUNJUNG | AB4: JUMLAH PETUGAS YG HADIR | AH4: JUMLAH BAYI | AL4: KET
C5: B A L I T A | L5: ANAK USIA 6-15 TAHUN | P5: USIA PRODUKTIF | T5: LANSIA | X5: WUS | Y5: IBU | AB5: KADER | AD5: PLKB | AF5: MEDIS DAN PARA MEDIS | AH5: YANG LAHIR | AJ5: MENINGGAL
C6: BAYI 0 - 12 BULAN | H6: BALITA 1-5 TAHUN | Y6: PUS | Z6: HAMIL | AA6: MENYUSUI
C7: BARU | E7: LAMA | G7: TOTAL | H7: BARU | J7: LAMA | L7: BARU | N7: LAMA | P7: BARU | R7: LAMA | T7: BARU | V7: LAMA
C8: L | D8: P | E8: L | F8: P | H8: L | I8: P | J8: L | K8: P | L8: L | M8: P | N8: L | O8: P | P8: L | Q8: P | R8: L | S8: P | T8: L | U8: P | V8: L | W8: P | AB8: L | AC8: P | AD8: L | AE8: P | AF8: L | AG8: P | AH8: L | AI8: P | AJ8: L | AK8: P
A9: 1 | B9: 2 | C9: 3 | D9: 4 | E9: 5 | F9: 6 | G9: 0 | H9: 7 | I9: 8 | J9: 9 | K9: 10 | L9: 11 | M9: 12 | N9: 13 | O9: 14 | P9: 15 | Q9: 16 | R9: 17 | S9: 18 | T9: 19 | U9: 20 | V9: 21 | W9: 22 | X9: 23 | Y9: 24 | Z9: 25 | AA9: 26 | AB9: 27 | AC9: 28 | AD9: 29 | AE9: 30 | AF9: 31 | AG9: 32 | AH9: 33 | AI9: 34 | AJ9: 35 | AK9: 36 | AL9: 37
A10: 1 | B10: JANUARI | C10: =SUM('KES SIP 6 MAWAR'!D10,'KES SIP 6 KENANGA'!F10,'KES SIP 6 DAHLIA'!C10,'KES SIP 6 MELATI'!C10) -> 0 | D10: =SUM('KES SIP 6 MAWAR'!E10,'KES SIP 6 KENANGA'!G10,'KES SIP 6 DAHLIA'!D10,'KES SIP 6 MELATI'!D10) -> 0 | E10: =SUM('KES SIP 6 MAWAR'!F10,'KES SIP 6 KENANGA'!I10,'KES SIP 6 DAHLIA'!E10,'KES SIP 6 MELATI'!E10) -> 0 | F10: =SUM('KES SIP 6 MAWAR'!G10,'KES SIP 6 KENANGA'!J10,'KES SIP 6 DAHLIA'!F10,'KES SIP 6 MELATI'!F10) -> 5 | G10: =SUM('KES SIP 6 MAWAR'!H10,'KES SIP 6 KENANGA'!K10,'KES SIP 6 DAHLIA'!G10,'KES SIP 6 MELATI'!G10) -> 5 | H10: =SUM('KES SIP 6 MAWAR'!I10,'KES SIP 6 KENANGA'!L10,'KES SIP 6 DAHLIA'!H10,'KES SIP 6 MELATI'!H10) -> 0 | I10: =SUM('KES SIP 6 MAWAR'!J10,'KES SIP 6 KENANGA'!M10,'KES SIP 6 DAHLIA'!I10,'KES SIP 6 MELATI'!I10) -> 2 | J10: =SUM('KES SIP 6 MAWAR'!K10,'KES SIP 6 KENANGA'!N10,'KES SIP 6 DAHLIA'!J10,'KES SIP 6 MELATI'!J10) -> 25 | K10: =SUM('KES SIP 6 MAWAR'!L10,'KES SIP 6 KENANGA'!O10,'KES SIP 6 DAHLIA'!K10,'KES SIP 6 MELATI'!K10) -> 48 | L10: =SUM('KES SIP 6 MAWAR'!M10,'KES SIP 6 KENANGA'!P10,'KES SIP 6 DAHLIA'!L10,'KES SIP 6 MELATI'!L10) -> 1 | ... AL10: =SUM('KES SIP 6 MAWAR'!AM10,'KES SIP 6 KENANGA'!AP10,'KES SIP 6 DAHLIA'!AL10,'KES SIP 6 MELATI'!AL10) -> 0
